Workbook

Sheet Peptide Map
A1: Peptide Map CMV gH (PEP20205091784) - Mouse Anti-CMV gH Antibody 13G1
A3: Microarray Content: | B3: Envelope glycoprotein H of CMV elongated with neutral GSGSGSG linkers at the C- and N-terminus and translated into overlapping peptides
A4: Sample: | B4: Mouse anti-CMV gH antibody 13G1
A5: Cyclization: | B5: N- to C-terminal thioether bridging
A6: Peptide Length: | B6: 7 aa, 10 aa and 13 aa
A7: Peptide Overlap: | B7: 6 aa, 9 aa and 12 aa
A8: Number of Peptides: | B8: 1815
A9: Number of Spots: | B9: 3.630 (peptides printed in duplicate)
A10: HA Controls: | B10: YPYDVPDYAG | C10: 128 spots
A13: Mouse antibody 13G1, 1 µg/ml | C13: 1 | D13: 2 | E13: 3 | F13: 4 | G13: 5 | H13: 6 | I13: 7 | J13: 8 | K13: 9 | L13: 10 | M13: 11 | N13: 12 | O13: 13 | P13: 14 | Q13: 15 | R13: 16 | S13: 17 | T13: 18 | U13: 19 | V13: 20 | W13: 21 | X13: 22 | Y13: 23 | Z13: 24 | AA13: 25 | AB13: 26 | AC13: 27 | AD13: 28 | AE13: 29 | AF13: 30 | AG13: 31 | AH13: 32 | AI13: 33 | AJ13: 34 | AK13: 35 | AL13: 36 | AM13: 37 | AN13: 38 | AO13: 39 | AP13: 40 | AQ13: 41 | AR13: 42 | AS13: 43 | AT13: 44 | AU13: 45 | AV13: 46 | AW13: 47 | AX13: 48 | AY13: 49 | AZ13: 50 | BA13: 51 | BB13: 52 | BC13: 53 | BD13: 54 | BE13: 55 | BF13: 56 | BG13: 57 | BH13: 58 | BI13: 59 | BJ13: 60 | BK13: 61 | BL13: 62 | BM13: 63 | BN13: 64 | BO13: 65 | BP13: 66
B14: YPYDVPDYAG | C14: G | D14: YPYDVPDYAG | E14: G | F14: YPYDVPDYAG | G14: G | H14: YPYDVPDYAG | I14: G | J14: YPYDVPDYAG | K14: G | L14: YPYDVPDYAG | M14: G | N14: YPYDVPDYAG | O14: G | P14: YPYDVPDYAG | Q14: G | R14: YPYDVPDYAG | S14: G | T14: YPYDVPDYAG | U14: G | V14: YPYDVPDYAG | W14: G | X14: YPYDVPDYAG | Y14: G | Z14: YPYDVPDYAG | AA14: G | AB14: YPYDVPDYAG | AC14: G | AD14: YPYDVPDYAG | AE14: G | AF14: YPYDVPDYAG | AG14: G | AH14: YPYDVPDYAG | AI14: G | AJ14: YPYDVPDYAG | AK14: G | AL14: YPYDVPDYAG | AM14: G | AN14: YPYDVPDYAG | AO14: G | AP14: YPYDVPDYAG | AQ14: G | AR14: YPYDVPDYAG | AS14: G | AT14: YPYDVPDYAG | AU14: G | AV14: YPYDVPDYAG | AW14: G | AX14: YPYDVPDYAG | AY14: G | AZ14: YPYDVPDYAG | BA14: G | BB14: YPYDVPDYAG | BC14: G | BD14: YPYDVPDYAG | BE14: G | BF14: YPYDVPDYAG | BG14: G | BH14: YPYDVPDYAG | BI14: G | BJ14: YPYDVPDYAG | BK14: G | BL14: YPYDVPDYAG | BM14: G | BN14: YPYDVPDYAG | BO14: G | BP14: YPYDVPDYAG | BQ14: G
A15: 1 | B15: YPYDVPDYAG | C15: GSGSGSG | D15: SGSGSGP | E15: GSGSGPL | F15: SGSGPLA | G15: GSGPLAE | H15: SGPLAEQ | I15: GPLAEQF | J15: PLAEQFL | K15: LAEQFLN | L15: AEQFLNQ | M15: EQFLNQV | N15: QFLNQVD | O15: FLNQVDL | P15: LNQVDLT | Q15: NQVDLTE | R15: QVDLTET | S15: VDLTETL | T15: DLTETLE | U15: LTETLER | V15: TETLERY | W15: ETLERYQ | X15: TLERYQQ | Y15: LERYQQR | Z15: ERYQQRL | AA15: RYQQRLN | AB15: YQQRLNT | AC15: QQRLNTY | AD15: QRLNTYA | AE15: RLNTYAL | AF15: LNTYALV | AG15: NTYALVS | AH15: TYALVSK | AI15: YALVSKD | AJ15: ALVSKDL | AK15: LVSKDLA | AL15: VSKDLAS | AM15: SKDLASY | AN15: KDLASYR | AO15: DLASYRS | AP15: LASYRSF | AQ15: ASYRSFS | AR15: SYRSFSQ | AS15: YRSFSQQ | AT15: RSFSQQL | AU15: SFSQQLK | AV15: FSQQLKA | AW15: SQQLKAQ | AX15: QQLKAQD | AY15: QLKAQDS | AZ15: LKAQDSL | BA15: KAQDSLG | BB15: AQDSLGQ | BC15: QDSLGQQ | BD15: DSLGQQP | BE15: SLGQQPT | BF15: LGQQPTT | BG15: GQQPTTV | BH15: QQPTTVP | BI15: QPTTVPP | BJ15: PTTVPPP | BK15: TTVPPPI | BL15: TVPPPID | BM15: VPPPIDL | BN15: PPPIDLS | BO15: PPIDLSI | BP15: PIDLSIP | BQ15: YPYDVPDYAG
A16: 2 | B16: G | C16: GSGSGSG | D16: SGSGSGP | E16: GSGSGPL | F16: SGSGPLA | G16: GSGPLAE | H16: SGPLAEQ | I16: GPLAEQF | J16: PLAEQFL | K16: LAEQFLN | L16: AEQFLNQ | M16: EQFLNQV | N16: QFLNQVD | O16: FLNQVDL | P16: LNQVDLT | Q16: NQVDLTE | R16: QVDLTET | S16: VDLTETL | T16: DLTETLE | U16: LTETLER | V16: TETLERY | W16: ETLERYQ | X16: TLERYQQ | Y16: LERYQQR | Z16: ERYQQRL | AA16: RYQQRLN | AB16: YQQRLNT | AC16: QQRLNTY | AD16: QRLNTYA | AE16: RLNTYAL | AF16: LNTYALV | AG16: NTYALVS | AH16: TYALVSK | AI16: YALVSKD | AJ16: ALVSKDL | AK16: LVSKDLA | AL16: VSKDLAS | AM16: SKDLASY | AN16: KDLASYR | AO16: DLASYRS | AP16: LASYRSF | AQ16: ASYRSFS | AR16: SYRSFSQ | AS16: YRSFSQQ | AT16: RSFSQQL | AU16: SFSQQLK | AV16: FSQQLKA | AW16: SQQLKAQ | AX16: QQLKAQD | AY16: QLKAQDS | AZ16: LKAQDSL | BA16: KAQDSLG | BB16: AQDSLGQ | BC16: QDSLGQQ | BD16: DSLGQQP | BE16: SLGQQPT | BF16: LGQQPTT | BG16: GQQPTTV | BH16: QQPTTVP | BI16: QPTTVPP | BJ16: PTTVPPP | BK16: TTVPPPI | BL16: TVPPPID | BM16: VPPPIDL | BN16: PPPIDLS | BO16: PPIDLSI | BP16: PIDLSIP | BQ16: G
A17: 3 | B17: YPYDVPDYAG | C17: IDLSIPH | D17: DLSIPHV | E17: LSIPHVW | F17: SIPHVWM | G17: IPHVWMP | H17: PHVWMPP | I17: HVWMPPQ | J17: VWMPPQT | K17: WMPPQTT | L17: MPPQTTP | M17: PPQTTPH | N17: PQTTPHD | O17: QTTPHDW | P17: TTPHDWK | Q17: TPHDWKG | R17: PHDWKGS | S17: HDWKGSH | T17: DWKGSHT | U17: WKGSHTT | V17: KGSHTTS | W17: GSHTTSG | X17: SHTTSGL | Y17: HTTSGLH | Z17: TTSGLHR | AA17: TSGLHRP | AB17: SGLHRPH | AC17: GLHRPHF | AD17: LHRPHFN | AE17: HRPHFNQ | AF17: RPHFNQT | AG17: PHFNQTC | AH17: HFNQTCI | AI17: FNQTCIL | AJ17: NQTCILF | AK17: QTCILFD | AL17: TCILFDG | AM17: CILFDGH | AN17: ILFDGHD | AO17: LFDGHDL | AP17: FDGHDLL | AQ17: DGHDLLF | AR17: GHDLLFS | AS17: HDLLFST | AT17: DLLFSTV | AU17: LLFSTVT | AV17: LFSTVTP | AW17: FSTVTPC | AX17: STVTPCL | AY17: TVTPCLH | AZ17: VTPCLHQ | BA17: TPCLHQG | BB17: PCLHQGF | BC17: CLHQGFY | BD17: LHQGFYL | BE17: HQGFYLM | BF17: QGFYLMD | BG17: GFYLMDE | BH17: FYLMDEL | BI17: YLMDELR | BJ17: LMDELRY | BK17: MDELRYV | BL17: DELRYVK | BM17: ELRYVKI | BN17: LRYVKIT | BO17: RYVKITL | BP17: YVKITLT | BQ17: YPYDVPDYAG
A18: 4 | B18: G | C18: IDLSIPH | D18: DLSIPHV | E18: LSIPHVW | F18: SIPHVWM | G18: IPHVWMP | H18: PHVWMPP | I18: HVWMPPQ | J18: VWMPPQT | K18: WMPPQTT | L18: MPPQTTP | M18: PPQTTPH | N18: PQTTPHD | O18: QTTPHDW | P18: TTPHDWK | Q18: TPHDWKG | R18: PHDWKGS | S18: HDWKGSH | T18: DWKGSHT | U18: WKGSHTT | V18: KGSHTTS | W18: GSHTTSG | X18: SHTTSGL | Y18: HTTSGLH | Z18: TTSGLHR | AA18: TSGLHRP | AB18: SGLHRPH | AC18: GLHRPHF | AD18: LHRPHFN | AE18: HRPHFNQ | AF18: RPHFNQT | AG18: PHFNQTC | AH18: HFNQTCI | AI18: FNQTCIL | AJ18: NQTCILF | AK18: QTCILFD | AL18: TCILFDG | AM18: CILFDGH | AN18: ILFDGHD | AO18: LFDGHDL | AP18: FDGHDLL | AQ18: DGHDLLF | AR18: GHDLLFS | AS18: HDLLFST | AT18: DLLFSTV | AU18: LLFSTVT | AV18: LFSTVTP | AW18: FSTVTPC | AX18: STVTPCL | AY18: TVTPCLH | AZ18: VTPCLHQ | BA18: TPCLHQG | BB18: PCLHQGF | BC18: CLHQGFY | BD18: LHQGFYL | BE18: HQGFYLM | BF18: QGFYLMD | BG18: GFYLMDE | BH18: FYLMDEL | BI18: YLMDELR | BJ18: LMDELRY | BK18: MDELRYV | BL18: DELRYVK | BM18: ELRYVKI | BN18: LRYVKIT | BO18: RYVKITL | BP18: YVKITLT | BQ18: G
A19: 5 | B19: YPYDVPDYAG | C19: VKITLTE | D19: KITLTED | E19: ITLTEDF | F19: TLTEDFF | G19: LTEDFFV | H19: TEDFFVV | I19: EDFFVVT | J19: DFFVVTV | K19: FFVVTVS | L19: FVVTVSI | M19: VVTVSID | N19: VTVSIDD | O19: TVSIDDD | P19: VSIDDDT | Q19: SIDDDTP | R19: IDDDTPM | S19: DDDTPML | T19: DDTPMLL | U19: DTPMLLI | V19: TPMLLIF | W19: PMLLIFG | X19: MLLIFGH | Y19: LLIFGHL | Z19: LIFGHLP | AA19: IFGHLPR | AB19: FGHLPRV | AC19: GHLPRVL | AD19: HLPRVLF | AE19: LPRVLFK | AF19: PRVLFKA | AG19: RVLFKAP | AH19: VLFKAPY | AI19: LFKAPYQ | AJ19: FKAPYQR | AK19: KAPYQRD | AL19: APYQRDN | AM19: PYQRDNF | AN19: YQRDNFI | AO19: QRDNFIL | AP19: RDNFILR | AQ19: DNFILRQ | AR19: NFILRQT | AS19: FILRQTE | AT19: ILRQTEK | AU19: LRQTEKH | AV19: RQTEKHE | AW19: QTEKHEL | AX19: TEKHELL | AY19: EKHELLV | AZ19: KHELLVL | BA19: HELLVLV | BB19: ELLVLVK | BC19: LLVLVKK | BD19: LVLVKKT | BE19: VLVKKTQ | BF19: LVKKTQL | BG19: VKKTQLN | BH19: KKTQLNR | BI19: KTQLNRH | BJ19: TQLNRHS | BK19: QLNRHSY | BL19: LNRHSYL | BM19: NRHSYLK | BN19: RHSYLKD | BO19: HSYLKDS | BP19: SYLKDSD | BQ19: YPYDVPDYAG
A20: 6 | B20: G | C20: VKITLTE | D20: KITLTED | E20: ITLTEDF | F20: TLTEDFF | G20: LTEDFFV | H20: TEDFFVV | I20: EDFFVVT | J20: DFFVVTV | K20: FFVVTVS | L20: FVVTVSI | M20: VVTVSID | N20: VTVSIDD | O20: TVSIDDD | P20: VSIDDDT | Q20: SIDDDTP | R20: IDDDTPM | S20: DDDTPML | T20: DDTPMLL | U20: DTPMLLI | V20: TPMLLIF | W20: PMLLIFG | X20: MLLIFGH | Y20: LLIFGHL | Z20: LIFGHLP | AA20: IFGHLPR | AB20: FGHLPRV | AC20: GHLPRVL | AD20: HLPRVLF | AE20: LPRVLFK | AF20: PRVLFKA | AG20: RVLFKAP | AH20: VLFKAPY | AI20: LFKAPYQ | AJ20: FKAPYQR | AK20: KAPYQRD | AL20: APYQRDN | AM20: PYQRDNF | AN20: YQRDNFI | AO20: QRDNFIL | AP20: RDNFILR | AQ20: DNFILRQ | AR20: NFILRQT | AS20: FILRQTE | AT20: ILRQTEK | AU20: LRQTEKH | AV20: RQTEKHE | AW20: QTEKHEL | AX20: TEKHELL | AY20: EKHELLV | AZ20: KHELLVL | BA20: HELLVLV | BB20: ELLVLVK | BC20: LLVLVKK | BD20: LVLVKKT | BE20: VLVKKTQ | BF20: LVKKTQL | BG20: VKKTQLN | BH20: KKTQLNR | BI20: KTQLNRH | BJ20: TQLNRHS | BK20: QLNRHSY | BL20: LNRHSYL | BM20: NRHSYLK | BN20: RHSYLKD | BO20: HSYLKDS | BP20: SYLKDSD | BQ20: G
A21: 7 | B21: YPYDVPDYAG | C21: YLKDSDF | D21: LKDSDFL | E21: KDSDFLD | F21: DSDFLDA | G21: SDFLDAA | H21: DFLDAAL | I21: FLDAALD | J21: LDAALDF | K21: DAALDFN | L21: AALDFNY | M21: ALDFNYL | N21: LDFNYLD | O21: DFNYLDL | P21: FNYLDLS | Q21: NYLDLSA | R21: YLDLSAL | S21: LDLSALL | T21: DLSALLR | U21: LSALLRN | V21: SALLRNS | W21: ALLRNSF | X21: LLRNSFH | Y21: LRNSFHR | Z21: RNSFHRY | AA21: NSFHRYA | AB21: SFHRYAV | AC21: FHRYAVD | AD21: HRYAVDV | AE21: RYAVDVL | AF21: YAVDVLK | AG21: AVDVLKS | AH21: VDVLKSG | AI21: DVLKSGR | AJ21: VLKSGRC | AK21: LKSGRCQ | AL21: KSGRCQM | AM21: SGRCQML | AN21: GRCQMLD | AO21: RCQMLDR | AP21: CQMLDRR | AQ21: QMLDRRT | AR21: MLDRRTV | AS21: LDRRTVE | AT21: DRRTVEM | AU21: RRTVEMA | AV21: RTVEMAF | AW21: TVEMAFA | AX21: VEMAFAY | AY21: EMAFAYA | AZ21: MAFAYAL | BA21: AFAYALA | BB21: FAYALAL | BC21: AYALALF | BD21: YALALFA | BE21: ALALFAA | BF21: LALFAAA | BG21: ALFAAAR | BH21: LFAAARQ | BI21: FAAARQE | BJ21: AAARQEE | BK21: AARQEEA | BL21: ARQEEAG | BM21: RQEEAGT | BN21: QEEAGTE | BO21: EEAGTEI | BP21: EAGTEIS | BQ21: YPYDVPDYAG
A22: 8 | B22: G | C22: YLKDSDF | D22: LKDSDFL | E22: KDSDFLD | F22: DSDFLDA | G22: SDFLDAA | H22: DFLDAAL | I22: FLDAALD | J22: LDAALDF | K22: DAALDFN | L22: AALDFNY | M22: ALDFNYL | N22: LDFNYLD | O22: DFNYLDL | P22: FNYLDLS | Q22: NYLDLSA | R22: YLDLSAL | S22: LDLSALL | T22: DLSALLR | U22: LSALLRN | V22: SALLRNS | W22: ALLRNSF | X22: LLRNSFH | Y22: LRNSFHR | Z22: RNSFHRY | AA22: NSFHRYA | AB22: SFHRYAV | AC22: FHRYAVD | AD22: HRYAVDV | AE22: RYAVDVL | AF22: YAVDVLK | AG22: AVDVLKS | AH22: VDVLKSG | AI22: DVLKSGR | AJ22: VLKSGRC | AK22: LKSGRCQ | AL22: KSGRCQM | AM22: SGRCQML | AN22: GRCQMLD | AO22: RCQMLDR | AP22: CQMLDRR | AQ22: QMLDRRT | AR22: MLDRRTV | AS22: LDRRTVE | AT22: DRRTVEM | AU22: RRTVEMA | AV22: RTVEMAF | AW22: TVEMAFA | AX22: VEMAFAY | AY22: EMAFAYA | AZ22: MAFAYAL | BA22: AFAYALA | BB22: FAYALAL | BC22: AYALALF | BD22: YALALFA | BE22: ALALFAA | BF22: LALFAAA | BG22: ALFAAAR | BH22: LFAAARQ | BI22: FAAARQE | BJ22: AAARQEE | BK22: AARQEEA | BL22: ARQEEAG | BM22: RQEEAGT | BN22: QEEAGTE | BO22: EEAGTEI | BP22: EAGTEIS | BQ22: G
A23: 9 | B23: YPYDVPDYAG | C23: AGTEISI | D23: GTEISIP | E23: TEISIPR | F23: EISIPRA | G23: ISIPRAL | H23: SIPRALD | I23: IPRALDR | J23: PRALDRQ | K23: RALDRQA | L23: ALDRQAA | M23: LDRQAAL | N23: DRQAALL | O23: RQAALLQ | P23: QAALLQI | Q23: AALLQIQ | R23: ALLQIQE | S23: LLQIQEF | T23: LQIQEFM | U23: QIQEFMI | V23: IQEFMIT | W23: QEFMITC | X23: EFMITCL | Y23: FMITCLS | Z23: MITCLSQ | AA23: ITCLSQT | AB23: TCLSQTP | AC23: CLSQTPP | AD23: LSQTPPR | AE23: SQTPPRT | AF23: QTPPRTT | AG23: TPPRTTL | AH23: PPRTTLL | AI23: PRTTLLL | AJ23: RTTLLLY | AK23: TTLLLYP | AL23: TLLLYPT | AM23: LLLYPTA | AN23: LLYPTAV | AO23: LYPTAVD | AP23: YPTAVDL | AQ23: PTAVDLA | AR23: TAVDLAK | AS23: AVDLAKR | AT23: VDLAKRA | AU23: DLAKRAL | AV23: LAKRALW | AW23: AKRALWT | AX23: KRALWTP | AY23: RALWTPD | AZ23: ALWTPDQ | BA23: LWTPDQI | BB23: WTPDQIT | BC23: TPDQITD | BD23: PDQITDI | BE23: DQITDIT | BF23: QITDITS | BG23: ITDITSL | BH23: TDITSLV | BI23: DITSLVR | BJ23: ITSLVRL | BK23: TSLVRLV | BL23: SLVRLVY | BM23: LVRLVYI | BN23: VRLVYIL | BO23: RLVYILS | BP23: LVYILSK | BQ23: YPYDVPDYAG
A24: 10 | B24: G | C24: AGTEISI | D24: GTEISIP | E24: TEISIPR | F24: EISIPRA | G24: ISIPRAL | H24: SIPRALD | I24: IPRALDR | J24: PRALDRQ | K24: RALDRQA | L24: ALDRQAA | M24: LDRQAAL | N24: DRQAALL | O24: RQAALLQ | P24: QAALLQI | Q24: AALLQIQ | R24: ALLQIQE | S24: LLQIQEF | T24: LQIQEFM | U24: QIQEFMI | V24: IQEFMIT | W24: QEFMITC | X24: EFMITCL | Y24: FMITCLS | Z24: MITCLSQ | AA24: ITCLSQT | AB24: TCLSQTP | AC24: CLSQTPP | AD24: LSQTPPR | AE24: SQTPPRT | AF24: QTPPRTT | AG24: TPPRTTL | AH24: PPRTTLL | AI24: PRTTLLL | AJ24: RTTLLLY | AK24: TTLLLYP | AL24: TLLLYPT | AM24: LLLYPTA | AN24: LLYPTAV | AO24: LYPTAVD | AP24: YPTAVDL | AQ24: PTAVDLA | AR24: TAVDLAK | AS24: AVDLAKR | AT24: VDLAKRA | AU24: DLAKRAL | AV24: LAKRALW | AW24: AKRALWT | AX24: KRALWTP | AY24: RALWTPD | AZ24: ALWTPDQ | BA24: LWTPDQI | BB24: WTPDQIT | BC24: TPDQITD | BD24: PDQITDI | BE24: DQITDIT | BF24: QITDITS | BG24: ITDITSL | BH24: TDITSLV | BI24: DITSLVR | BJ24: ITSLVRL | BK24: TSLVRLV | BL24: SLVRLVY | BM24: LVRLVYI | BN24: VRLVYIL | BO24: RLVYILS | BP24: LVYILSK | BQ24: G
A25: 11 | B25: YPYDVPDYAG | C25: VYILSKQ | D25: YILSKQN | E25: ILSKQNQ | F25: LSKQNQQ | G25: SKQNQQH | H25: KQNQQHL | I25: QNQQHLI | J25: NQQHLIP | K25: QQHLIPQ | L25: QHLIPQW | M25: HLIPQWA | N25: LIPQWAL | O25: IPQWALR | P25: PQWALRQ | Q25: QWALRQI | R25: WALRQIA | S25: ALRQIAD | T25: LRQIADF | U25: RQIADFA | V25: QIADFAL | W25: IADFALQ | X25: ADFALQL | Y25: DFALQLH | Z25: FALQLHK | AA25: ALQLHKT | AB25: LQLHKTH | AC25: QLHKTHL | AD25: LHKTHLA | AE25: HKTHLAS | AF25: KTHLASF | AG25: THLASFL | AH25: HLASFLS | AI25: LASFLSA | AJ25: ASFLSAF | AK25: SFLSAFA | AL25: FLSAFAR | AM25: LSAFARQ | AN25: SAFARQE | AO25: AFARQEL | AP25: FARQELY | AQ25: ARQELYL | AR25: RQELYLM | AS25: QELYLMG | AT25: ELYLMGS | AU25: LYLMGSL | AV25: YLMGSLV | AW25: LMGSLVH | AX25: MGSLVHS | AY25: GSLVHSM | AZ25: SLVHSML | BA25: LVHSMLV | BB25: VHSMLVH | BC25: HSMLVHT | BD25: SMLVHTT | BE25: MLVHTTE | BF25: LVHTTER | BG25: VHTTERR | BH25: HTTERRE | BI25: TTERREI | BJ25: TERREIF | BK25: ERREIFI | BL25: RREIFIV | BM25: REIFIVE | BN25: EIFIVET | BO25: IFIVETG | BP25: FIVETGL | BQ25: YPYDVPDYAG
A26: 12 | B26: G | C26: VYILSKQ | D26: YILSKQN | E26: ILSKQNQ | F26: LSKQNQQ | G26: SKQNQQH | H26: KQNQQHL | I26: QNQQHLI | J26: NQQHLIP | K26: QQHLIPQ | L26: QHLIPQW | M26: HLIPQWA | N26: LIPQWAL | O26: IPQWALR | P26: PQWALRQ | Q26: QWALRQI | R26: WALRQIA | S26: ALRQIAD | T26: LRQIADF | U26: RQIADFA | V26: QIADFAL | W26: IADFALQ | X26: ADFALQL | Y26: DFALQLH | Z26: FALQLHK | AA26: ALQLHKT | AB26: LQLHKTH | AC26: QLHKTHL | AD26: LHKTHLA | AE26: HKTHLAS | AF26: KTHLASF | AG26: THLASFL | AH26: HLASFLS | AI26: LASFLSA | AJ26: ASFLSAF | AK26: SFLSAFA | AL26: FLSAFAR | AM26: LSAFARQ | AN26: SAFARQE | AO26: AFARQEL | AP26: FARQELY | AQ26: ARQELYL | AR26: RQELYLM | AS26: QELYLMG | AT26: ELYLMGS | AU26: LYLMGSL | AV26: YLMGSLV | AW26: LMGSLVH | AX26: MGSLVHS | AY26: GSLVHSM | AZ26: SLVHSML | BA26: LVHSMLV | BB26: VHSMLVH | BC26: HSMLVHT | BD26: SMLVHTT | BE26: MLVHTTE | BF26: LVHTTER | BG26: VHTTERR | BH26: HTTERRE | BI26: TTERREI | BJ26: TERREIF | BK26: ERREIFI | BL26: RREIFIV | BM26: REIFIVE | BN26: EIFIVET | BO26: IFIVETG | BP26: FIVETGL | BQ26: G
... A32: 18 | B32: G | C32: QSKCELT | D32: SKCELTR | E32: KCELTRN | F32: CELTRNM | G32: ELTRNMH | H32: LTRNMHT | I32: TRNMHTT | J32: RNMHTTH | K32: NMHTTHS | L32: MHTTHSI | M32: HTTHSIT | N32: TTHSITA | O32: THSITAA | P32: HSITAAL | Q32: SITAALN | R32: ITAALNI | S32: TAALNIS | T32: AALNISL | U32: ALNISLE | V32: LNISLEN | W32: NISLENC | X32: ISLENCA | Y32: SLENCAF | Z32: LENCAFC | AA32: ENCAFCQ | AB32: NCAFCQS | AC32: CAFCQSA | AD32: AFCQSAL | AE32: FCQSALL | AF32: CQSALLE | AG32: QSALLEY | AH32: SALLEYD | AI32: ALLEYDD | AJ32: LLEYDDT | AK32: LEYDDTQ | AL32: EYDDTQG | AM32: YDDTQGV | AN32: DDTQGVI | AO32: DTQGVIN | AP32: TQGVINI | AQ32: QGVINIM | AR32: GVINIMY | AS32: VINIMYM | AT32: INIMYMH | AU32: NIMYMHD | AV32: IMYMHDS | AW32: MYMHDSD | AX32: YMHDSDD | AY32: MHDSDDV | AZ32: HDSDDVL | BA32: DSDDVLF | BB32: SDDVLFA | BC32: DDVLFAL | BD32: DVLFALD | BE32: VLFALDP | BF32: LFALDPY | BG32: FALDPYN | BH32: ALDPYNE | BI32: LDPYNEV | BJ32: DPYNEVV | BK32: PYNEVVV | BL32: YNEVVVS | BM32: NEVVVSS | BN32: EVVVSSP | BO32: VVVSSPR | BP32: VVSSPRT | BQ32: G
A33: 19 | B33: YPYDVPDYAG | C33: VSSPRTH | D33: SSPRTHY | E33: SPRTHYL | F33: PRTHYLM | G33: RTHYLML | H33: THYLMLL | I33: HYLMLLK | J33: YLMLLKG | K33: LMLLKGS | L33: MLLKGSG | M33: LLKGSGS | N33: LKGSGSG | O33: KGSGSGS | P33: GSGSGSG | BQ33: YPYDVPDYAG
A34: 20 | B34: G | C34: VSSPRTH | D34: SSPRTHY | E34: SPRTHYL | F34: PRTHYLM | G34: RTHYLML | H34: THYLMLL | I34: HYLMLLK | J34: YLMLLKG | K34: LMLLKGS | L34: MLLKGSG | M34: LLKGSGS | N34: LKGSGSG | O34: KGSGSGS | P34: GSGSGSG | BQ34: G
A35: 21 | B35: YPYDVPDYAG | C35: GSGSGSGPLA | D35: SGSGSGPLAE | E35: GSGSGPLAEQ | F35: SGSGPLAEQF | G35: GSGPLAEQFL | H35: SGPLAEQFLN | I35: GPLAEQFLNQ | J35: PLAEQFLNQV | K35: LAEQFLNQVD | L35: AEQFLNQVDL | M35: EQFLNQVDLT | N35: QFLNQVDLTE | O35: FLNQVDLTET | P35: LNQVDLTETL | Q35: NQVDLTETLE | R35: QVDLTETLER | S35: VDLTETLERY | T35: DLTETLERYQ | U35: LTETLERYQQ | V35: TETLERYQQR | W35: ETLERYQQRL | X35: TLERYQQRLN | Y35: LERYQQRLNT | Z35: ERYQQRLNTY | AA35: RYQQRLNTYA | AB35: YQQRLNTYAL | AC35: QQRLNTYALV | AD35: QRLNTYALVS | AE35: RLNTYALVSK | AF35: LNTYALVSKD | AG35: NTYALVSKDL | AH35: TYALVSKDLA | AI35: YALVSKDLAS | AJ35: ALVSKDLASY | AK35: LVSKDLASYR | AL35: VSKDLASYRS | AM35: SKDLASYRSF | AN35: KDLASYRSFS | AO35: DLASYRSFSQ | AP35: LASYRSFSQQ | AQ35: ASYRSFSQQL | AR35: SYRSFSQQLK | AS35: YRSFSQQLKA | AT35: RSFSQQLKAQ | AU35: SFSQQLKAQD | AV35: FSQQLKAQDS | AW35: SQQLKAQDSL | AX35: QQLKAQDSLG | AY35: QLKAQDSLGQ | AZ35: LKAQDSLGQQ | BA35: KAQDSLGQQP | BB35: AQDSLGQQPT | BC35: QDSLGQQPTT | BD35: DSLGQQPTTV | BE35: SLGQQPTTVP | BF35: LGQQPTTVPP | BG35: GQQPTTVPPP | BH35: QQPTTVPPPI | BI35: QPTTVPPPID | BJ35: PTTVPPPIDL | BK35: TTVPPPIDLS | BL35: TVPPPIDLSI | BM35: VPPPIDLSIP | BN35: PPPIDLSIPH | BO35: PPIDLSIPHV | BP35: PIDLSIPHVW | BQ35: YPYDVPDYAG
A36: 22 | B36: G | C36: GSGSGSGPLA | D36: SGSGSGPLAE | E36: GSGSGPLAEQ | F36: SGSGPLAEQF | G36: GSGPLAEQFL | H36: SGPLAEQFLN | I36: GPLAEQFLNQ | J36: PLAEQFLNQV | K36: LAEQFLNQVD | L36: AEQFLNQVDL | M36: EQFLNQVDLT | N36: QFLNQVDLTE | O36: FLNQVDLTET | P36: LNQVDLTETL | Q36: NQVDLTETLE | R36: QVDLTETLER | S36: VDLTETLERY | T36: DLTETLERYQ | U36: LTETLERYQQ | V36: TETLERYQQR | W36: ETLERYQQRL | X36: TLERYQQRLN | Y36: LERYQQRLNT | Z36: ERYQQRLNTY | AA36: RYQQRLNTYA | AB36: YQQRLNTYAL | AC36: QQRLNTYALV | AD36: QRLNTYALVS | AE36: RLNTYALVSK | AF36: LNTYALVSKD | AG36: NTYALVSKDL | AH36: TYALVSKDLA | AI36: YALVSKDLAS | AJ36: ALVSKDLASY | AK36: LVSKDLASYR | AL36: VSKDLASYRS | AM36: SKDLASYRSF | AN36: KDLASYRSFS | AO36: DLASYRSFSQ | AP36: LASYRSFSQQ | AQ36: ASYRSFSQQL | AR36: SYRSFSQQLK | AS36: YRSFSQQLKA | AT36: RSFSQQLKAQ | AU36: SFSQQLKAQD | AV36: FSQQLKAQDS | AW36: SQQLKAQDSL | AX36: QQLKAQDSLG | AY36: QLKAQDSLGQ | AZ36: LKAQDSLGQQ | BA36: KAQDSLGQQP | BB36: AQDSLGQQPT | BC36: QDSLGQQPTT | BD36: DSLGQQPTTV | BE36: SLGQQPTTVP | BF36: LGQQPTTVPP | BG36: GQQPTTVPPP | BH36: QQPTTVPPPI | BI36: QPTTVPPPID | BJ36: PTTVPPPIDL | BK36: TTVPPPIDLS | BL36: TVPPPIDLSI | BM36: VPPPIDLSIP | BN36: PPPIDLSIPH | BO36: PPIDLSIPHV | BP36: PIDLSIPHVW | BQ36: G
A37: 23 | B37: YPYDVPDYAG | C37: IDLSIPHVWM | D37: DLSIPHVWMP | E37: LSIPHVWMPP | F37: SIPHVWMPPQ | G37: IPHVWMPPQT | H37: PHVWMPPQTT | I37: HVWMPPQTTP | J37: VWMPPQTTPH | K37: WMPPQTTPHD | L37: MPPQTTPHDW | M37: PPQTTPHDWK | N37: PQTTPHDWKG | O37: QTTPHDWKGS | P37: TTPHDWKGSH | Q37: TPHDWKGSHT | R37: PHDWKGSHTT | S37: HDWKGSHTTS | T37: DWKGSHTTSG | U37: WKGSHTTSGL | V37: KGSHTTSGLH | W37: GSHTTSGLHR | X37: SHTTSGLHRP | Y37: HTTSGLHRPH | Z37: TTSGLHRPHF | AA37: TSGLHRPHFN | AB37: SGLHRPHFNQ | AC37: GLHRPHFNQT | AD37: LHRPHFNQTC | AE37: HRPHFNQTCI | AF37: RPHFNQTCIL | AG37: PHFNQTCILF | AH37: HFNQTCILFD | AI37: FNQTCILFDG | AJ37: NQTCILFDGH | AK37: QTCILFDGHD | AL37: TCILFDGHDL | AM37: CILFDGHDLL | AN37: ILFDGHDLLF | AO37: LFDGHDLLFS | AP37: FDGHDLLFST | AQ37: DGHDLLFSTV | AR37: GHDLLFSTVT | AS37: HDLLFSTVTP | AT37: DLLFSTVTPC | AU37: LLFSTVTPCL | AV37: LFSTVTPCLH | AW37: FSTVTPCLHQ | AX37: STVTPCLHQG | AY37: TVTPCLHQGF | AZ37: VTPCLHQGFY | BA37: TPCLHQGFYL | BB37: PCLHQGFYLM | BC37: CLHQGFYLMD | BD37: LHQGFYLMDE | BE37: HQGFYLMDEL | BF37: QGFYLMDELR | BG37: GFYLMDELRY | BH37: FYLMDELRYV | BI37: YLMDELRYVK | BJ37: LMDELRYVKI | BK37: MDELRYVKIT | BL37: DELRYVKITL | BM37: ELRYVKITLT | BN37: LRYVKITLTE | BO37: RYVKITLTED | BP37: YVKITLTEDF | BQ37: YPYDVPDYAG
A38: 24 | B38: G | C38: IDLSIPHVWM | D38: DLSIPHVWMP | E38: LSIPHVWMPP | F38: SIPHVWMPPQ | G38: IPHVWMPPQT | H38: PHVWMPPQTT | I38: HVWMPPQTTP | J38: VWMPPQTTPH | K38: WMPPQTTPHD | L38: MPPQTTPHDW | M38: PPQTTPHDWK | N38: PQTTPHDWKG | O38: QTTPHDWKGS | P38: TTPHDWKGSH | Q38: TPHDWKGSHT | R38: PHDWKGSHTT | S38: HDWKGSHTTS | T38: DWKGSHTTSG | U38: WKGSHTTSGL | V38: KGSHTTSGLH | W38: GSHTTSGLHR | X38: SHTTSGLHRP | Y38: HTTSGLHRPH | Z38: TTSGLHRPHF | AA38: TSGLHRPHFN | AB38: SGLHRPHFNQ | AC38: GLHRPHFNQT | AD38: LHRPHFNQTC | AE38: HRPHFNQTCI | AF38: RPHFNQTCIL | AG38: PHFNQTCILF | AH38: HFNQTCILFD | AI38: FNQTCILFDG | AJ38: NQTCILFDGH | AK38: QTCILFDGHD | AL38: TCILFDGHDL | AM38: CILFDGHDLL | AN38: ILFDGHDLLF | AO38: LFDGHDLLFS | AP38: FDGHDLLFST | AQ38: DGHDLLFSTV | AR38: GHDLLFSTVT | AS38: HDLLFSTVTP | AT38: DLLFSTVTPC | AU38: LLFSTVTPCL | AV38: LFSTVTPCLH | AW38: FSTVTPCLHQ | AX38: STVTPCLHQG | AY38: TVTPCLHQGF | AZ38: VTPCLHQGFY | BA38: TPCLHQGFYL | BB38: PCLHQGFYLM | BC38: CLHQGFYLMD | BD38: LHQGFYLMDE | BE38: HQGFYLMDEL | BF38: QGFYLMDELR | BG38: GFYLMDELRY | BH38: FYLMDELRYV | BI38: YLMDELRYVK | BJ38: LMDELRYVKI | BK38: MDELRYVKIT | BL38: DELRYVKITL | BM38: ELRYVKITLT | BN38: LRYVKITLTE | BO38: RYVKITLTED | BP38: YVKITLTEDF | BQ38: G
A39: 25 | B39: YPYDVPDYAG | C39: VKITLTEDFF | D39: KITLTEDFFV | E39: ITLTEDFFVV | F39: TLTEDFFVVT | G39: LTEDFFVVTV | H39: TEDFFVVTVS | I39: EDFFVVTVSI | J39: DFFVVTVSID | K39: FFVVTVSIDD | L39: FVVTVSIDDD | M39: VVTVSIDDDT | N39: VTVSIDDDTP | O39: TVSIDDDTPM | P39: VSIDDDTPML | Q39: SIDDDTPMLL | R39: IDDDTPMLLI | S39: DDDTPMLLIF | T39: DDTPMLLIFG | U39: DTPMLLIFGH | V39: TPMLLIFGHL | W39: PMLLIFGHLP | X39: MLLIFGHLPR | Y39: LLIFGHLPRV | Z39: LIFGHLPRVL | AA39: IFGHLPRVLF | AB39: FGHLPRVLFK | AC39: GHLPRVLFKA | AD39: HLPRVLFKAP | AE39: LPRVLFKAPY | AF39: PRVLFKAPYQ | AG39: RVLFKAPYQR | AH39: VLFKAPYQRD | AI39: LFKAPYQRDN | AJ39: FKAPYQRDNF | AK39: KAPYQRDNFI | AL39: APYQRDNFIL | AM39: PYQRDNFILR | AN39: YQRDNFILRQ | AO39: QRDNFILRQT | AP39: RDNFILRQTE | AQ39: DNFILRQTEK | AR39: NFILRQTEKH | AS39: FILRQTEKHE | AT39: ILRQTEKHEL | AU39: LRQTEKHELL | AV39: RQTEKHELLV | AW39: QTEKHELLVL | AX39: TEKHELLVLV | AY39: EKHELLVLVK | AZ39: KHELLVLVKK | BA39: HELLVLVKKT | BB39: ELLVLVKKTQ | BC39: LLVLVKKTQL | BD39: LVLVKKTQLN | BE39: VLVKKTQLNR | BF39: LVKKTQLNRH | BG39: VKKTQLNRHS | BH39: KKTQLNRHSY | BI39: KTQLNRHSYL | BJ39: TQLNRHSYLK | BK39: QLNRHSYLKD | BL39: LNRHSYLKDS | BM39: NRHSYLKDSD | BN39: RHSYLKDSDF | BO39: HSYLKDSDFL | BP39: SYLKDSDFLD | BQ39: YPYDVPDYAG
A40: 26 | B40: G | C40: VKITLTEDFF | D40: KITLTEDFFV | E40: ITLTEDFFVV | F40: TLTEDFFVVT | G40: LTEDFFVVTV | H40: TEDFFVVTVS | I40: EDFFVVTVSI | J40: DFFVVTVSID | K40: FFVVTVSIDD | L40: FVVTVSIDDD | M40: VVTVSIDDDT | N40: VTVSIDDDTP | O40: TVSIDDDTPM | P40: VSIDDDTPML | Q40: SIDDDTPMLL | R40: IDDDTPMLLI | S40: DDDTPMLLIF | T40: DDTPMLLIFG | U40: DTPMLLIFGH | V40: TPMLLIFGHL | W40: PMLLIFGHLP | X40: MLLIFGHLPR | Y40: LLIFGHLPRV | Z40: LIFGHLPRVL | AA40: IFGHLPRVLF | AB40: FGHLPRVLFK | AC40: GHLPRVLFKA | AD40: HLPRVLFKAP | AE40: LPRVLFKAPY | AF40: PRVLFKAPYQ | AG40: RVLFKAPYQR | AH40: VLFKAPYQRD | AI40: LFKAPYQRDN | AJ40: FKAPYQRDNF | AK40: KAPYQRDNFI | AL40: APYQRDNFIL | AM40: PYQRDNFILR | AN40: YQRDNFILRQ | AO40: QRDNFILRQT | AP40: RDNFILRQTE | AQ40: DNFILRQTEK | AR40: NFILRQTEKH | AS40: FILRQTEKHE | AT40: ILRQTEKHEL | AU40: LRQTEKHELL | AV40: RQTEKHELLV | AW40: QTEKHELLVL | AX40: TEKHELLVLV | AY40: EKHELLVLVK | AZ40: KHELLVLVKK | BA40: HELLVLVKKT | BB40: ELLVLVKKTQ | BC40: LLVLVKKTQL | BD40: LVLVKKTQLN | BE40: VLVKKTQLNR | BF40: LVKKTQLNRH | BG40: VKKTQLNRHS | BH40: KKTQLNRHSY | BI40: KTQLNRHSYL | BJ40: TQLNRHSYLK | BK40: QLNRHSYLKD | BL40: LNRHSYLKDS | BM40: NRHSYLKDSD | BN40: RHSYLKDSDF | BO40: HSYLKDSDFL | BP40: SYLKDSDFLD | BQ40: G
A41: 27 | B41: YPYDVPDYAG | C41: YLKDSDFLDA | D41: LKDSDFLDAA | E41: KDSDFLDAAL | F41: DSDFLDAALD | G41: SDFLDAALDF | H41: DFLDAALDFN | I41: FLDAALDFNY | J41: LDAALDFNYL | K41: DAALDFNYLD | L41: AALDFNYLDL | M41: ALDFNYLDLS | N41: LDFNYLDLSA | O41: DFNYLDLSAL | P41: FNYLDLSALL | Q41: NYLDLSALLR | R41: YLDLSALLRN | S41: LDLSALLRNS | T41: DLSALLRNSF | U41: LSALLRNSFH | V41: SALLRNSFHR | W41: ALLRNSFHRY | X41: LLRNSFHRYA | Y41: LRNSFHRYAV | Z41: RNSFHRYAVD | AA41: NSFHRYAVDV | AB41: SFHRYAVDVL | AC41: FHRYAVDVLK | AD41: HRYAVDVLKS | AE41: RYAVDVLKSG | AF41: YAVDVLKSGR | AG41: AVDVLKSGRC | AH41: VDVLKSGRCQ | AI41: DVLKSGRCQM | AJ41: VLKSGRCQML | AK41: LKSGRCQMLD | AL41: KSGRCQMLDR | AM41: SGRCQMLDRR | AN41: GRCQMLDRRT | AO41: RCQMLDRRTV | AP41: CQMLDRRTVE | AQ41: QMLDRRTVEM | AR41: MLDRRTVEMA | AS41: LDRRTVEMAF | AT41: DRRTVEMAFA | AU41: RRTVEMAFAY | AV41: RTVEMAFAYA | AW41: TVEMAFAYAL | AX41: VEMAFAYALA | AY41: EMAFAYALAL | AZ41: MAFAYALALF | BA41: AFAYALALFA | BB41: FAYALALFAA | BC41: AYALALFAAA | BD41: YALALFAAAR | BE41: ALALFAAARQ | BF41: LALFAAARQE | BG41: ALFAAARQEE | BH41: LFAAARQEEA | BI41: FAAARQEEAG | BJ41: AAARQEEAGT | BK41: AARQEEAGTE | BL41: ARQEEAGTEI | BM41: RQEEAGTEIS | BN41: QEEAGTEISI | BO41: EEAGTEISIP | BP41: EAGTEISIPR | BQ41: YPYDVPDYAG
A42: 28 | B42: G | C42: YLKDSDFLDA | D42: LKDSDFLDAA | E42: KDSDFLDAAL | F42: DSDFLDAALD | G42: SDFLDAALDF | H42: DFLDAALDFN | I42: FLDAALDFNY | J42: LDAALDFNYL | K42: DAALDFNYLD | L42: AALDFNYLDL | M42: ALDFNYLDLS | N42: LDFNYLDLSA | O42: DFNYLDLSAL | P42: FNYLDLSALL | Q42: NYLDLSALLR | R42: YLDLSALLRN | S42: LDLSALLRNS | T42: DLSALLRNSF | U42: LSALLRNSFH | V42: SALLRNSFHR | W42: ALLRNSFHRY | X42: LLRNSFHRYA | Y42: LRNSFHRYAV | Z42: RNSFHRYAVD | AA42: NSFHRYAVDV | AB42: SFHRYAVDVL | AC42: FHRYAVDVLK | AD42: HRYAVDVLKS | AE42: RYAVDVLKSG | AF42: YAVDVLKSGR | AG42: AVDVLKSGRC | AH42: VDVLKSGRCQ | AI42: DVLKSGRCQM | AJ42: VLKSGRCQML | AK42: LKSGRCQMLD | AL42: KSGRCQMLDR | AM42: SGRCQMLDRR | AN42: GRCQMLDRRT | AO42: RCQMLDRRTV | AP42: CQMLDRRTVE | AQ42: QMLDRRTVEM | AR42: MLDRRTVEMA | AS42: LDRRTVEMAF | AT42: DRRTVEMAFA | AU42: RRTVEMAFAY | AV42: RTVEMAFAYA | AW42: TVEMAFAYAL | AX42: VEMAFAYALA | AY42: EMAFAYALAL | AZ42: MAFAYALALF | BA42: AFAYALALFA | BB42: FAYALALFAA | BC42: AYALALFAAA | BD42: YALALFAAAR | BE42: ALALFAAARQ | BF42: LALFAAARQE | BG42: ALFAAARQEE | BH42: LFAAARQEEA | BI42: FAAARQEEAG | BJ42: AAARQEEAGT | BK42: AARQEEAGTE | BL42: ARQEEAGTEI | BM42: RQEEAGTEIS | BN42: QEEAGTEISI | BO42: EEAGTEISIP | BP42: EAGTEISIPR | BQ42: G
A43: 29 | B43: YPYDVPDYAG | C43: AGTEISIPRA | D43: GTEISIPRAL | E43: TEISIPRALD | F43: EISIPRALDR | G43: ISIPRALDRQ | H43: SIPRALDRQA | I43: IPRALDRQAA | J43: PRALDRQAAL | K43: RALDRQAALL | L43: ALDRQAALLQ | M43: LDRQAALLQI | N43: DRQAALLQIQ | O43: RQAALLQIQE | P43: QAALLQIQEF | Q43: AALLQIQEFM | R43: ALLQIQEFMI | S43: LLQIQEFMIT | T43: LQIQEFMITC | U43: QIQEFMITCL | V43: IQEFMITCLS | W43: QEFMITCLSQ | X43: EFMITCLSQT | Y43: FMITCLSQTP | Z43: MITCLSQTPP | AA43: ITCLSQTPPR | AB43: TCLSQTPPRT | AC43: CLSQTPPRTT | AD43: LSQTPPRTTL | AE43: SQTPPRTTLL | AF43: QTPPRTTLLL | AG43: TPPRTTLLLY | AH43: PPRTTLLLYP | AI43: PRTTLLLYPT | AJ43: RTTLLLYPTA | AK43: TTLLLYPTAV | AL43: TLLLYPTAVD | AM43: LLLYPTAVDL | AN43: LLYPTAVDLA | AO43: LYPTAVDLAK | AP43: YPTAVDLAKR | AQ43: PTAVDLAKRA | AR43: TAVDLAKRAL | AS43: AVDLAKRALW | AT43: VDLAKRALWT | AU43: DLAKRALWTP | AV43: LAKRALWTPD | AW43: AKRALWTPDQ | AX43: KRALWTPDQI | AY43: RALWTPDQIT | AZ43: ALWTPDQITD | BA43: LWTPDQITDI | BB43: WTPDQITDIT | BC43: TPDQITDITS | BD43: PDQITDITSL | BE43: DQITDITSLV | BF43: QITDITSLVR | BG43: ITDITSLVRL | BH43: TDITSLVRLV | BI43: DITSLVRLVY | BJ43: ITSLVRLVYI | BK43: TSLVRLVYIL | BL43: SLVRLVYILS | BM43: LVRLVYILSK | BN43: VRLVYILSKQ | BO43: RLVYILSKQN | BP43: LVYILSKQNQ | BQ43: YPYDVPDYAG
A44: 30 | B44: G | C44: AGTEISIPRA | D44: GTEISIPRAL | E44: TEISIPRALD | F44: EISIPRALDR | G44: ISIPRALDRQ | H44: SIPRALDRQA | I44: IPRALDRQAA | J44: PRALDRQAAL | K44: RALDRQAALL | L44: ALDRQAALLQ | M44: LDRQAALLQI | N44: DRQAALLQIQ | O44: RQAALLQIQE | P44: QAALLQIQEF | Q44: AALLQIQEFM | R44: ALLQIQEFMI | S44: LLQIQEFMIT | T44: LQIQEFMITC | U44: QIQEFMITCL | V44: IQEFMITCLS | W44: QEFMITCLSQ | X44: EFMITCLSQT | Y44: FMITCLSQTP | Z44: MITCLSQTPP | AA44: ITCLSQTPPR | AB44: TCLSQTPPRT | AC44: CLSQTPPRTT | AD44: LSQTPPRTTL | AE44: SQTPPRTTLL | AF44: QTPPRTTLLL | AG44: TPPRTTLLLY | AH44: PPRTTLLLYP | AI44: PRTTLLLYPT | AJ44: RTTLLLYPTA | AK44: TTLLLYPTAV | AL44: TLLLYPTAVD | AM44: LLLYPTAVDL | AN44: LLYPTAVDLA | AO44: LYPTAVDLAK | AP44: YPTAVDLAKR | AQ44: PTAVDLAKRA | AR44: TAVDLAKRAL | AS44: AVDLAKRALW | AT44: VDLAKRALWT | AU44: DLAKRALWTP | AV44: LAKRALWTPD | AW44: AKRALWTPDQ | AX44: KRALWTPDQI | AY44: RALWTPDQIT | AZ44: ALWTPDQITD | BA44: LWTPDQITDI | BB44: WTPDQITDIT | BC44: TPDQITDITS | BD44: PDQITDITSL | BE44: DQITDITSLV | BF44: QITDITSLVR | BG44: ITDITSLVRL | BH44: TDITSLVRLV | BI44: DITSLVRLVY | BJ44: ITSLVRLVYI | BK44: TSLVRLVYIL | BL44: SLVRLVYILS | BM44: LVRLVYILSK | BN44: VRLVYILSKQ | BO44: RLVYILSKQN | BP44: LVYILSKQNQ | BQ44: G
A45: 31 | B45: YPYDVPDYAG | C45: VYILSKQNQQ | D45: YILSKQNQQH | E45: ILSKQNQQHL | F45: LSKQNQQHLI | G45: SKQNQQHLIP | H45: KQNQQHLIPQ | I45: QNQQHLIPQW | J45: NQQHLIPQWA | K45: QQHLIPQWAL | L45: QHLIPQWALR | M45: HLIPQWALRQ | N45: LIPQWALRQI | O45: IPQWALRQIA | P45: PQWALRQIAD | Q45: QWALRQIADF | R45: WALRQIADFA | S45: ALRQIADFAL | T45: LRQIADFALQ | U45: RQIADFALQL | V45: QIADFALQLH | W45: IADFALQLHK | X45: ADFALQLHKT | Y45: DFALQLHKTH | Z45: FALQLHKTHL | AA45: ALQLHKTHLA | AB45: LQLHKTHLAS | AC45: QLHKTHLASF | AD45: LHKTHLASFL | AE45: HKTHLASFLS | AF45: KTHLASFLSA | AG45: THLASFLSAF | AH45: HLASFLSAFA | AI45: LASFLSAFAR | AJ45: ASFLSAFARQ | AK45: SFLSAFARQE | AL45: FLSAFARQEL | AM45: LSAFARQELY | AN45: SAFARQELYL | AO45: AFARQELYLM | AP45: FARQELYLMG | AQ45: ARQELYLMGS | AR45: RQELYLMGSL | AS45: QELYLMGSLV | AT45: ELYLMGSLVH | AU45: LYLMGSLVHS | AV45: YLMGSLVHSM | AW45: LMGSLVHSML | AX45: MGSLVHSMLV | AY45: GSLVHSMLVH | AZ45: SLVHSMLVHT | BA45: LVHSMLVHTT | BB45: VHSMLVHTTE | BC45: HSMLVHTTER | BD45: SMLVHTTERR | BE45: MLVHTTERRE | BF45: LVHTTERREI | BG45: VHTTERREIF | BH45: HTTERREIFI | BI45: TTERREIFIV | BJ45: TERREIFIVE | BK45: ERREIFIVET | BL45: RREIFIVETG | BM45: REIFIVETGL | BN45: EIFIVETGLC | BO45: IFIVETGLCS | BP45: FIVETGLCSL | BQ45: YPYDVPDYAG
A46: 32 | B46: G | C46: VYILSKQNQQ | D46: YILSKQNQQH | E46: ILSKQNQQHL | F46: LSKQNQQHLI | G46: SKQNQQHLIP | H46: KQNQQHLIPQ | I46: QNQQHLIPQW | J46: NQQHLIPQWA | K46: QQHLIPQWAL | L46: QHLIPQWALR | M46: HLIPQWALRQ | N46: LIPQWALRQI | O46: IPQWALRQIA | P46: PQWALRQIAD | Q46: QWALRQIADF | R46: WALRQIADFA | S46: ALRQIADFAL | T46: LRQIADFALQ | U46: RQIADFALQL | V46: QIADFALQLH | W46: IADFALQLHK | X46: ADFALQLHKT | Y46: DFALQLHKTH | Z46: FALQLHKTHL | AA46: ALQLHKTHLA | AB46: LQLHKTHLAS | AC46: QLHKTHLASF | AD46: LHKTHLASFL | AE46: HKTHLASFLS | AF46: KTHLASFLSA | AG46: THLASFLSAF | AH46: HLASFLSAFA | AI46: LASFLSAFAR | AJ46: ASFLSAFARQ | AK46: SFLSAFARQE | AL46: FLSAFARQEL | AM46: LSAFARQELY | AN46: SAFARQELYL | AO46: AFARQELYLM | AP46: FARQELYLMG | AQ46: ARQELYLMGS | AR46: RQELYLMGSL | AS46: QELYLMGSLV | AT46: ELYLMGSLVH | AU46: LYLMGSLVHS | AV46: YLMGSLVHSM | AW46: LMGSLVHSML | AX46: MGSLVHSMLV | AY46: GSLVHSMLVH | AZ46: SLVHSMLVHT | BA46: LVHSMLVHTT | BB46: VHSMLVHTTE | BC46: HSMLVHTTER | BD46: SMLVHTTERR | BE46: MLVHTTERRE | BF46: LVHTTERREI | BG46: VHTTERREIF | BH46: HTTERREIFI | BI46: TTERREIFIV | BJ46: TERREIFIVE | BK46: ERREIFIVET | BL46: RREIFIVETG | BM46: REIFIVETGL | BN46: EIFIVETGLC | BO46: IFIVETGLCS | BP46: FIVETGLCSL | BQ46: G
... A52: 38 | B52: G | C52: QSKCELTRNM | D52: SKCELTRNMH | E52: KCELTRNMHT | F52: CELTRNMHTT | G52: ELTRNMHTTH | H52: LTRNMHTTHS | I52: TRNMHTTHSI | J52: RNMHTTHSIT | K52: NMHTTHSITA | L52: MHTTHSITAA | M52: HTTHSITAAL | N52: TTHSITAALN | O52: THSITAALNI | P52: HSITAALNIS | Q52: SITAALNISL | R52: ITAALNISLE | S52: TAALNISLEN | T52: AALNISLENC | U52: ALNISLENCA | V52: LNISLENCAF | W52: NISLENCAFC | X52: ISLENCAFCQ | Y52: SLENCAFCQS | Z52: LENCAFCQSA | AA52: ENCAFCQSAL | AB52: NCAFCQSALL | AC52: CAFCQSALLE | AD52: AFCQSALLEY | AE52: FCQSALLEYD | AF52: CQSALLEYDD | AG52: QSALLEYDDT | AH52: SALLEYDDTQ | AI52: ALLEYDDTQG | AJ52: LLEYDDTQGV | AK52: LEYDDTQGVI | AL52: EYDDTQGVIN | AM52: YDDTQGVINI | AN52: DDTQGVINIM | AO52: DTQGVINIMY | AP52: TQGVINIMYM | AQ52: QGVINIMYMH | AR52: GVINIMYMHD | AS52: VINIMYMHDS | AT52: INIMYMHDSD | AU52: NIMYMHDSDD | AV52: IMYMHDSDDV | AW52: MYMHDSDDVL | AX52: YMHDSDDVLF | AY52: MHDSDDVLFA | AZ52: HDSDDVLFAL | BA52: DSDDVLFALD | BB52: SDDVLFALDP | BC52: DDVLFALDPY | BD52: DVLFALDPYN | BE52: VLFALDPYNE | BF52: LFALDPYNEV | BG52: FALDPYNEVV | BH52: ALDPYNEVVV | BI52: LDPYNEVVVS | BJ52: DPYNEVVVSS | BK52: PYNEVVVSSP | BL52: YNEVVVSSPR | BM52: NEVVVSSPRT | BN52: EVVVSSPRTH | BO52: VVVSSPRTHY | BP52: VVSSPRTHYL | BQ52: G
A53: 39 | B53: YPYDVPDYAG | C53: VSSPRTHYLM | D53: SSPRTHYLML | E53: SPRTHYLMLL | F53: PRTHYLMLLK | G53: RTHYLMLLKG | H53: THYLMLLKGS | I53: HYLMLLKGSG | J53: YLMLLKGSGS | K53: LMLLKGSGSG | L53: MLLKGSGSGS | M53: LLKGSGSGSG | BQ53: YPYDVPDYAG
...

Sheet Intensity Map
A1: Intensity Map CMV gH (PEP20205091784) - Mouse Anti-CMV gH Antibody 13G1
A3: Microarray Content: | B3: Envelope glycoprotein H of CMV elongated with neutral GSGSGSG linkers at the C- and N-terminus and translated into overlapping peptides
A4: Sample: | B4: Mouse anti-CMV gH antibody 13G1
A5: Cyclization: | B5: N- to C-terminal thioether bridging
A6: Peptide Length: | B6: 7 aa, 10 aa and 13 aa
A7: Peptide Overlap: | B7: 6 aa, 9 aa and 12 aa
A8: Number of Peptides: | B8: 1815
A9: Number of Spots: | B9: 3.630 (peptides printed in duplicate)
A10: HA Controls: | B10: YPYDVPDYAG | C10: 128 spots
A13: Mouse antibody 13G1, 1 µg/ml | C13: 1 | D13: 2 | E13: 3 | F13: 4 | G13: 5 | H13: 6 | I13: 7 | J13: 8 | K13: 9 | L13: 10 | M13: 11 | N13: 12 | O13: 13 | P13: 14 | Q13: 15 | R13: 16 | S13: 17 | T13: 18 | U13: 19 | V13: 20 | W13: 21 | X13: 22 | Y13: 23 | Z13: 24 | AA13: 25 | AB13: 26 | AC13: 27 | AD13: 28 | AE13: 29 | AF13: 30 | AG13: 31 | AH13: 32 | AI13: 33 | AJ13: 34 | AK13: 35 | AL13: 36 | AM13: 37 | AN13: 38 | AO13: 39 | AP13: 40 | AQ13: 41 | AR13: 42 | AS13: 43 | AT13: 44 | AU13: 45 | AV13: 46 | AW13: 47 | AX13: 48 | AY13: 49 | AZ13: 50 | BA13: 51 | BB13: 52 | BC13: 53 | BD13: 54 | BE13: 55 | BF13: 56 | BG13: 57 | BH13: 58 | BI13: 59 | BJ13: 60 | BK13: 61 | BL13: 62 | BM13: 63 | BN13: 64 | BO13: 65 | BP13: 66
B14: YPYDVPDYAG | C14: G | D14: YPYDVPDYAG | E14: G | F14: YPYDVPDYAG | G14: G | H14: YPYDVPDYAG | I14: G | J14: YPYDVPDYAG | K14: G | L14: YPYDVPDYAG | M14: G | N14: YPYDVPDYAG | O14: G | P14: YPYDVPDYAG | Q14: G | R14: YPYDVPDYAG | S14: G | T14: YPYDVPDYAG | U14: G | V14: YPYDVPDYAG | W14: G | X14: YPYDVPDYAG | Y14: G | Z14: YPYDVPDYAG | AA14: G | AB14: YPYDVPDYAG | AC14: G | AD14: YPYDVPDYAG | AE14: G | AF14: YPYDVPDYAG | AG14: G | AH14: YPYDVPDYAG | AI14: G | AJ14: YPYDVPDYAG | AK14: G | AL14: YPYDVPDYAG | AM14: G | AN14: YPYDVPDYAG | AO14: G | AP14: YPYDVPDYAG | AQ14: G | AR14: YPYDVPDYAG | AS14: G | AT14: YPYDVPDYAG | AU14: G | AV14: YPYDVPDYAG | AW14: G | AX14: YPYDVPDYAG | AY14: G | AZ14: YPYDVPDYAG | BA14: G | BB14: YPYDVPDYAG | BC14: G | BD14: YPYDVPDYAG | BE14: G | BF14: YPYDVPDYAG | BG14: G | BH14: YPYDVPDYAG | BI14: G | BJ14: YPYDVPDYAG | BK14: G | BL14: YPYDVPDYAG | BM14: G | BN14: YPYDVPDYAG | BO14: G | BP14: YPYDVPDYAG | BQ14: G
A15: 1 | B15: YPYDVPDYAG | C15: =INDEX('Mapping Summary'!$H$6:$H$1820,MATCH('Peptide Map'!C15,'Mapping Summary'!$D$6:$D$1820,0)) -> 0 | D15: =INDEX('Mapping Summary'!$H$6:$H$1820,MATCH('Peptide Map'!D15,'Mapping Summary'!$D$6:$D$1820,0)) -> 0 | E15: =INDEX('Mapping Summary'!$H$6:$H$1820,MATCH('Peptide Map'!E15,'Mapping Summary'!$D$6:$D$1820,0)) -> 0 | F15: =INDEX('Mapping Summary'!$H$6:$H$1820,MATCH('Peptide Map'!F15,'Mapping Summary'!$D$6:$D$1820,0)) -> 0 | G15: =INDEX('Mapping Summary'!$H$6:$H$1820,MATCH('Peptide Map'!G15,'Mapping Summary'!$D$6:$D$1820,0)) -> 8.5 | H15: =INDEX('Mapping Summary'!$H$6:$H$1820,MATCH('Peptide Map'!H15,'Mapping Summary'!$D$6:$D$1820,0)) -> 0 | I15: =INDEX('Mapping Summary'!$H$6:$H$1820,MATCH('Peptide Map'!I15,'Mapping Summary'!$D$6:$D$1820,0)) -> 3.5 | J15: =INDEX('Mapping Summary'!$H$6:$H$1820,MATCH('Peptide Map'!J15,'Mapping Summary'!$D$6:$D$1820,0)) -> 8.5 | ... BP15: =INDEX('Mapping Summary'!$H$6:$H$1820,MATCH('Peptide Map'!BP15,'Mapping Summary'!$D$6:$D$1820,0)) -> 15.25 | BQ15: YPYDVPDYAG
A16: 2 | B16: G | C16: =INDEX('Mapping Summary'!$H$6:$H$1820,MATCH('Peptide Map'!C16,'Mapping Summary'!$D$6:$D$1820,0)) -> 0 | D16: =INDEX('Mapping Summary'!$H$6:$H$1820,MATCH('Peptide Map'!D16,'Mapping Summary'!$D$6:$D$1820,0)) -> 0 | E16: =INDEX('Mapping Summary'!$H$6:$H$1820,MATCH('Peptide Map'!E16,'Mapping Summary'!$D$6:$D$1820,0)) -> 0 | F16: =INDEX('Mapping Summary'!$H$6:$H$1820,MATCH('Peptide Map'!F16,'Mapping Summary'!$D$6:$D$1820,0)) -> 0 | G16: =INDEX('Mapping Summary'!$H$6:$H$1820,MATCH('Peptide Map'!G16,'Mapping Summary'!$D$6:$D$1820,0)) -> 8.5 | H16: =INDEX('Mapping Summary'!$H$6:$H$1820,MATCH('Peptide Map'!H16,'Mapping Summary'!$D$6:$D$1820,0)) -> 0 | I16: =INDEX('Mapping Summary'!$H$6:$H$1820,MATCH('Peptide Map'!I16,'Mapping Summary'!$D$6:$D$1820,0)) -> 3.5 | J16: =INDEX('Mapping Summary'!$H$6:$H$1820,MATCH('Peptide Map'!J16,'Mapping Summary'!$D$6:$D$1820,0)) -> 8.5 | ... BP16: =INDEX('Mapping Summary'!$H$6:$H$1820,MATCH('Peptide Map'!BP16,'Mapping Summary'!$D$6:$D$1820,0)) -> 15.25 | BQ16: G
A17: 3 | B17: YPYDVPDYAG | C17: =INDEX('Mapping Summary'!$H$6:$H$1820,MATCH('Peptide Map'!C17,'Mapping Summary'!$D$6:$D$1820,0)) -> 9 | D17: =INDEX('Mapping Summary'!$H$6:$H$1820,MATCH('Peptide Map'!D17,'Mapping Summary'!$D$6:$D$1820,0)) -> 0 | E17: =INDEX('Mapping Summary'!$H$6:$H$1820,MATCH('Peptide Map'!E17,'Mapping Summary'!$D$6:$D$1820,0)) -> 0 | F17: =INDEX('Mapping Summary'!$H$6:$H$1820,MATCH('Peptide Map'!F17,'Mapping Summary'!$D$6:$D$1820,0)) -> 0 | G17: =INDEX('Mapping Summary'!$H$6:$H$1820,MATCH('Peptide Map'!G17,'Mapping Summary'!$D$6:$D$1820,0)) -> 3 | H17: =INDEX('Mapping Summary'!$H$6:$H$1820,MATCH('Peptide Map'!H17,'Mapping Summary'!$D$6:$D$1820,0)) -> 0 | I17: =INDEX('Mapping Summary'!$H$6:$H$1820,MATCH('Peptide Map'!I17,'Mapping Summary'!$D$6:$D$1820,0)) -> 6.5 | J17: =INDEX('Mapping Summary'!$H$6:$H$1820,MATCH('Peptide Map'!J17,'Mapping Summary'!$D$6:$D$1820,0)) -> 0 | ... BP17: =INDEX('Mapping Summary'!$H$6:$H$1820,MATCH('Peptide Map'!BP17,'Mapping Summary'!$D$6:$D$1820,0)) -> 0 | BQ17: YPYDVPDYAG
A18: 4 | B18: G | C18: =INDEX('Mapping Summary'!$H$6:$H$1820,MATCH('Peptide Map'!C18,'Mapping Summary'!$D$6:$D$1820,0)) -> 9 | D18: =INDEX('Mapping Summary'!$H$6:$H$1820,MATCH('Peptide Map'!D18,'Mapping Summary'!$D$6:$D$1820,0)) -> 0 | E18: =INDEX('Mapping Summary'!$H$6:$H$1820,MATCH('Peptide Map'!E18,'Mapping Summary'!$D$6:$D$1820,0)) -> 0 | F18: =INDEX('Mapping Summary'!$H$6:$H$1820,MATCH('Peptide Map'!F18,'Mapping Summary'!$D$6:$D$1820,0)) -> 0 | G18: =INDEX('Mapping Summary'!$H$6:$H$1820,MATCH('Peptide Map'!G18,'Mapping Summary'!$D$6:$D$1820,0)) -> 3 | H18: =INDEX('Mapping Summary'!$H$6:$H$1820,MATCH('Peptide Map'!H18,'Mapping Summary'!$D$6:$D$1820,0)) -> 0 | I18: =INDEX('Mapping Summary'!$H$6:$H$1820,MATCH('Peptide Map'!I18,'Mapping Summary'!$D$6:$D$1820,0)) -> 6.5 | J18: =INDEX('Mapping Summary'!$H$6:$H$1820,MATCH('Peptide Map'!J18,'Mapping Summary'!$D$6:$D$1820,0)) -> 0 | ... BP18: =INDEX('Mapping Summary'!$H$6:$H$1820,MATCH('Peptide Map'!BP18,'Mapping Summary'!$D$6:$D$1820,0)) -> 0 | BQ18: G
A19: 5 | B19: YPYDVPDYAG | C19: =INDEX('Mapping Summary'!$H$6:$H$1820,MATCH('Peptide Map'!C19,'Mapping Summary'!$D$6:$D$1820,0)) -> 0 | D19: =INDEX('Mapping Summary'!$H$6:$H$1820,MATCH('Peptide Map'!D19,'Mapping Summary'!$D$6:$D$1820,0)) -> 2 | E19: =INDEX('Mapping Summary'!$H$6:$H$1820,MATCH('Peptide Map'!E19,'Mapping Summary'!$D$6:$D$1820,0)) -> 0 | F19: =INDEX('Mapping Summary'!$H$6:$H$1820,MATCH('Peptide Map'!F19,'Mapping Summary'!$D$6:$D$1820,0)) -> 7.5 | G19: =INDEX('Mapping Summary'!$H$6:$H$1820,MATCH('Peptide Map'!G19,'Mapping Summary'!$D$6:$D$1820,0)) -> 0 | H19: =INDEX('Mapping Summary'!$H$6:$H$1820,MATCH('Peptide Map'!H19,'Mapping Summary'!$D$6:$D$1820,0)) -> 8 | I19: =INDEX('Mapping Summary'!$H$6:$H$1820,MATCH('Peptide Map'!I19,'Mapping Summary'!$D$6:$D$1820,0)) -> 0 | J19: =INDEX('Mapping Summary'!$H$6:$H$1820,MATCH('Peptide Map'!J19,'Mapping Summary'!$D$6:$D$1820,0)) -> 4.5 | ... BP19: =INDEX('Mapping Summary'!$H$6:$H$1820,MATCH('Peptide Map'!BP19,'Mapping Summary'!$D$6:$D$1820,0)) -> 0 | BQ19: YPYDVPDYAG
A20: 6 | B20: G | C20: =INDEX('Mapping Summary'!$H$6:$H$1820,MATCH('Peptide Map'!C20,'Mapping Summary'!$D$6:$D$1820,0)) -> 0 | D20: =INDEX('Mapping Summary'!$H$6:$H$1820,MATCH('Peptide Map'!D20,'Mapping Summary'!$D$6:$D$1820,0)) -> 2 | E20: =INDEX('Mapping Summary'!$H$6:$H$1820,MATCH('Peptide Map'!E20,'Mapping Summary'!$D$6:$D$1820,0)) -> 0 | F20: =INDEX('Mapping Summary'!$H$6:$H$1820,MATCH('Peptide Map'!F20,'Mapping Summary'!$D$6:$D$1820,0)) -> 7.5 | G20: =INDEX('Mapping Summary'!$H$6:$H$1820,MATCH('Peptide Map'!G20,'Mapping Summary'!$D$6:$D$1820,0)) -> 0 | H20: =INDEX('Mapping Summary'!$H$6:$H$1820,MATCH('Peptide Map'!H20,'Mapping Summary'!$D$6:$D$1820,0)) -> 8 | I20: =INDEX('Mapping Summary'!$H$6:$H$1820,MATCH('Peptide Map'!I20,'Mapping Summary'!$D$6:$D$1820,0)) -> 0 | J20: =INDEX('Mapping Summary'!$H$6:$H$1820,MATCH('Peptide Map'!J20,'Mapping Summary'!$D$6:$D$1820,0)) -> 4.5 | ... BP20: =INDEX('Mapping Summary'!$H$6:$H$1820,MATCH('Peptide Map'!BP20,'Mapping Summary'!$D$6:$D$1820,0)) -> 0 | BQ20: G
A21: 7 | B21: YPYDVPDYAG | C21: =INDEX('Mapping Summary'!$H$6:$H$1820,MATCH('Peptide Map'!C21,'Mapping Summary'!$D$6:$D$1820,0)) -> 0 | D21: =INDEX('Mapping Summary'!$H$6:$H$1820,MATCH('Peptide Map'!D21,'Mapping Summary'!$D$6:$D$1820,0)) -> 0 | E21: =INDEX('Mapping Summary'!$H$6:$H$1820,MATCH('Peptide Map'!E21,'Mapping Summary'!$D$6:$D$1820,0)) -> 4.5 | F21: =INDEX('Mapping Summary'!$H$6:$H$1820,MATCH('Peptide Map'!F21,'Mapping Summary'!$D$6:$D$1820,0)) -> 5 | G21: =INDEX('Mapping Summary'!$H$6:$H$1820,MATCH('Peptide Map'!G21,'Mapping Summary'!$D$6:$D$1820,0)) -> 0 | H21: =INDEX('Mapping Summary'!$H$6:$H$1820,MATCH('Peptide Map'!H21,'Mapping Summary'!$D$6:$D$1820,0)) -> 0 | I21: =INDEX('Mapping Summary'!$H$6:$H$1820,MATCH('Peptide Map'!I21,'Mapping Summary'!$D$6:$D$1820,0)) -> 7 | J21: =INDEX('Mapping Summary'!$H$6:$H$1820,MATCH('Peptide Map'!J21,'Mapping Summary'!$D$6:$D$1820,0)) -> 4 | ... BP21: =INDEX('Mapping Summary'!$H$6:$H$1820,MATCH('Peptide Map'!BP21,'Mapping Summary'!$D$6:$D$1820,0)) -> 4.5 | BQ21: YPYDVPDYAG
A22: 8 | B22: G | C22: =INDEX('Mapping Summary'!$H$6:$H$1820,MATCH('Peptide Map'!C22,'Mapping Summary'!$D$6:$D$1820,0)) -> 0 | D22: =INDEX('Mapping Summary'!$H$6:$H$1820,MATCH('Peptide Map'!D22,'Mapping Summary'!$D$6:$D$1820,0)) -> 0 | E22: =INDEX('Mapping Summary'!$H$6:$H$1820,MATCH('Peptide Map'!E22,'Mapping Summary'!$D$6:$D$1820,0)) -> 4.5 | F22: =INDEX('Mapping Summary'!$H$6:$H$1820,MATCH('Peptide Map'!F22,'Mapping Summary'!$D$6:$D$1820,0)) -> 5 | G22: =INDEX('Mapping Summary'!$H$6:$H$1820,MATCH('Peptide Map'!G22,'Mapping Summary'!$D$6:$D$1820,0)) -> 0 | H22: =INDEX('Mapping Summary'!$H$6:$H$1820,MATCH('Peptide Map'!H22,'Mapping Summary'!$D$6:$D$1820,0)) -> 0 | I22: =INDEX('Mapping Summary'!$H$6:$H$1820,MATCH('Peptide Map'!I22,'Mapping Summary'!$D$6:$D$1820,0)) -> 7 | J22: =INDEX('Mapping Summary'!$H$6:$H$1820,MATCH('Peptide Map'!J22,'Mapping Summary'!$D$6:$D$1820,0)) -> 4 | ... BP22: =INDEX('Mapping Summary'!$H$6:$H$1820,MATCH('Peptide Map'!BP22,'Mapping Summary'!$D$6:$D$1820,0)) -> 4.5 | BQ22: G
A23: 9 | B23: YPYDVPDYAG | C23: =INDEX('Mapping Summary'!$H$6:$H$1820,MATCH('Peptide Map'!C23,'Mapping Summary'!$D$6:$D$1820,0)) -> 0 | D23: =INDEX('Mapping Summary'!$H$6:$H$1820,MATCH('Peptide Map'!D23,'Mapping Summary'!$D$6:$D$1820,0)) -> 0 | E23: =INDEX('Mapping Summary'!$H$6:$H$1820,MATCH('Peptide Map'!E23,'Mapping Summary'!$D$6:$D$1820,0)) -> 0 | F23: =INDEX('Mapping Summary'!$H$6:$H$1820,MATCH('Peptide Map'!F23,'Mapping Summary'!$D$6:$D$1820,0)) -> 0 | G23: =INDEX('Mapping Summary'!$H$6:$H$1820,MATCH('Peptide Map'!G23,'Mapping Summary'!$D$6:$D$1820,0)) -> 0 | H23: =INDEX('Mapping Summary'!$H$6:$H$1820,MATCH('Peptide Map'!H23,'Mapping Summary'!$D$6:$D$1820,0)) -> 0 | I23: =INDEX('Mapping Summary'!$H$6:$H$1820,MATCH('Peptide Map'!I23,'Mapping Summary'!$D$6:$D$1820,0)) -> 2 | J23: =INDEX('Mapping Summary'!$H$6:$H$1820,MATCH('Peptide Map'!J23,'Mapping Summary'!$D$6:$D$1820,0)) -> 0 | ... BP23: =INDEX('Mapping Summary'!$H$6:$H$1820,MATCH('Peptide Map'!BP23,'Mapping Summary'!$D$6:$D$1820,0)) -> 0 | BQ23: YPYDVPDYAG
A24: 10 | B24: G | C24: =INDEX('Mapping Summary'!$H$6:$H$1820,MATCH('Peptide Map'!C24,'Mapping Summary'!$D$6:$D$1820,0)) -> 0 | D24: =INDEX('Mapping Summary'!$H$6:$H$1820,MATCH('Peptide Map'!D24,'Mapping Summary'!$D$6:$D$1820,0)) -> 0 | E24: =INDEX('Mapping Summary'!$H$6:$H$1820,MATCH('Peptide Map'!E24,'Mapping Summary'!$D$6:$D$1820,0)) -> 0 | F24: =INDEX('Mapping Summary'!$H$6:$H$1820,MATCH('Peptide Map'!F24,'Mapping Summary'!$D$6:$D$1820,0)) -> 0 | G24: =INDEX('Mapping Summary'!$H$6:$H$1820,MATCH('Peptide Map'!G24,'Mapping Summary'!$D$6:$D$1820,0)) -> 0 | H24: =INDEX('Mapping Summary'!$H$6:$H$1820,MATCH('Peptide Map'!H24,'Mapping Summary'!$D$6:$D$1820,0)) -> 0 | I24: =INDEX('Mapping Summary'!$H$6:$H$1820,MATCH('Peptide Map'!I24,'Mapping Summary'!$D$6:$D$1820,0)) -> 2 | J24: =INDEX('Mapping Summary'!$H$6:$H$1820,MATCH('Peptide Map'!J24,'Mapping Summary'!$D$6:$D$1820,0)) -> 0 | ... BP24: =INDEX('Mapping Summary'!$H$6:$H$1820,MATCH('Peptide Map'!BP24,'Mapping Summary'!$D$6:$D$1820,0)) -> 0 | BQ24: G
A25: 11 | B25: YPYDVPDYAG | C25: =INDEX('Mapping Summary'!$H$6:$H$1820,MATCH('Peptide Map'!C25,'Mapping Summary'!$D$6:$D$1820,0)) -> 0 | D25: =INDEX('Mapping Summary'!$H$6:$H$1820,MATCH('Peptide Map'!D25,'Mapping Summary'!$D$6:$D$1820,0)) -> 0 | E25: =INDEX('Mapping Summary'!$H$6:$H$1820,MATCH('Peptide Map'!E25,'Mapping Summary'!$D$6:$D$1820,0)) -> 0 | F25: =INDEX('Mapping Summary'!$H$6:$H$1820,MATCH('Peptide Map'!F25,'Mapping Summary'!$D$6:$D$1820,0)) -> 0 | G25: =INDEX('Mapping Summary'!$H$6:$H$1820,MATCH('Peptide Map'!G25,'Mapping Summary'!$D$6:$D$1820,0)) -> 0 | H25: =INDEX('Mapping Summary'!$H$6:$H$1820,MATCH('Peptide Map'!H25,'Mapping Summary'!$D$6:$D$1820,0)) -> 0 | I25: =INDEX('Mapping Summary'!$H$6:$H$1820,MATCH('Peptide Map'!I25,'Mapping Summary'!$D$6:$D$1820,0)) -> 0 | J25: =INDEX('Mapping Summary'!$H$6:$H$1820,MATCH('Peptide Map'!J25,'Mapping Summary'!$D$6:$D$1820,0)) -> 0 | ... BP25: =INDEX('Mapping Summary'!$H$6:$H$1820,MATCH('Peptide Map'!BP25,'Mapping Summary'!$D$6:$D$1820,0)) -> 0 | BQ25: YPYDVPDYAG
A26: 12 | B26: G | C26: =INDEX('Mapping Summary'!$H$6:$H$1820,MATCH('Peptide Map'!C26,'Mapping Summary'!$D$6:$D$1820,0)) -> 0 | D26: =INDEX('Mapping Summary'!$H$6:$H$1820,MATCH('Peptide Map'!D26,'Mapping Summary'!$D$6:$D$1820,0)) -> 0 | E26: =INDEX('Mapping Summary'!$H$6:$H$1820,MATCH('Peptide Map'!E26,'Mapping Summary'!$D$6:$D$1820,0)) -> 0 | F26: =INDEX('Mapping Summary'!$H$6:$H$1820,MATCH('Peptide Map'!F26,'Mapping Summary'!$D$6:$D$1820,0)) -> 0 | G26: =INDEX('Mapping Summary'!$H$6:$H$1820,MATCH('Peptide Map'!G26,'Mapping Summary'!$D$6:$D$1820,0)) -> 0 | H26: =INDEX('Mapping Summary'!$H$6:$H$1820,MATCH('Peptide Map'!H26,'Mapping Summary'!$D$6:$D$1820,0)) -> 0 | I26: =INDEX('Mapping Summary'!$H$6:$H$1820,MATCH('Peptide Map'!I26,'Mapping Summary'!$D$6:$D$1820,0)) -> 0 | J26: =INDEX('Mapping Summary'!$H$6:$H$1820,MATCH('Peptide Map'!J26,'Mapping Summary'!$D$6:$D$1820,0)) -> 0 | ... BP26: =INDEX('Mapping Summary'!$H$6:$H$1820,MATCH('Peptide Map'!BP26,'Mapping Summary'!$D$6:$D$1820,0)) -> 0 | BQ26: G
... A32: 18 | B32: G | C32: =INDEX('Mapping Summary'!$H$6:$H$1820,MATCH('Peptide Map'!C32,'Mapping Summary'!$D$6:$D$1820,0)) -> 0 | D32: =INDEX('Mapping Summary'!$H$6:$H$1820,MATCH('Peptide Map'!D32,'Mapping Summary'!$D$6:$D$1820,0)) -> 0 | E32: =INDEX('Mapping Summary'!$H$6:$H$1820,MATCH('Peptide Map'!E32,'Mapping Summary'!$D$6:$D$1820,0)) -> 4 | F32: =INDEX('Mapping Summary'!$H$6:$H$1820,MATCH('Peptide Map'!F32,'Mapping Summary'!$D$6:$D$1820,0)) -> 0 | G32: =INDEX('Mapping Summary'!$H$6:$H$1820,MATCH('Peptide Map'!G32,'Mapping Summary'!$D$6:$D$1820,0)) -> 0 | H32: =INDEX('Mapping Summary'!$H$6:$H$1820,MATCH('Peptide Map'!H32,'Mapping Summary'!$D$6:$D$1820,0)) -> 0 | I32: =INDEX('Mapping Summary'!$H$6:$H$1820,MATCH('Peptide Map'!I32,'Mapping Summary'!$D$6:$D$1820,0)) -> 0 | J32: =INDEX('Mapping Summary'!$H$6:$H$1820,MATCH('Peptide Map'!J32,'Mapping Summary'!$D$6:$D$1820,0)) -> 0 | ... BP32: =INDEX('Mapping Summary'!$H$6:$H$1820,MATCH('Peptide Map'!BP32,'Mapping Summary'!$D$6:$D$1820,0)) -> 0 | BQ32: G
A33: 19 | B33: YPYDVPDYAG | C33: =INDEX('Mapping Summary'!$H$6:$H$1820,MATCH('Peptide Map'!C33,'Mapping Summary'!$D$6:$D$1820,0)) -> 0 | D33: =INDEX('Mapping Summary'!$H$6:$H$1820,MATCH('Peptide Map'!D33,'Mapping Summary'!$D$6:$D$1820,0)) -> 0 | E33: =INDEX('Mapping Summary'!$H$6:$H$1820,MATCH('Peptide Map'!E33,'Mapping Summary'!$D$6:$D$1820,0)) -> 0 | F33: =INDEX('Mapping Summary'!$H$6:$H$1820,MATCH('Peptide Map'!F33,'Mapping Summary'!$D$6:$D$1820,0)) -> 0 | G33: =INDEX('Mapping Summary'!$H$6:$H$1820,MATCH('Peptide Map'!G33,'Mapping Summary'!$D$6:$D$1820,0)) -> 0 | H33: =INDEX('Mapping Summary'!$H$6:$H$1820,MATCH('Peptide Map'!H33,'Mapping Summary'!$D$6:$D$1820,0)) -> 0 | I33: =INDEX('Mapping Summary'!$H$6:$H$1820,MATCH('Peptide Map'!I33,'Mapping Summary'!$D$6:$D$1820,0)) -> 0 | J33: =INDEX('Mapping Summary'!$H$6:$H$1820,MATCH('Peptide Map'!J33,'Mapping Summary'!$D$6:$D$1820,0)) -> 0 | ... P33: =INDEX('Mapping Summary'!$H$6:$H$1820,MATCH('Peptide Map'!P33,'Mapping Summary'!$D$6:$D$1820,0)) -> 0 | BQ33: YPYDVPDYAG
A34: 20 | B34: G | C34: =INDEX('Mapping Summary'!$H$6:$H$1820,MATCH('Peptide Map'!C34,'Mapping Summary'!$D$6:$D$1820,0)) -> 0 | D34: =INDEX('Mapping Summary'!$H$6:$H$1820,MATCH('Peptide Map'!D34,'Mapping Summary'!$D$6:$D$1820,0)) -> 0 | E34: =INDEX('Mapping Summary'!$H$6:$H$1820,MATCH('Peptide Map'!E34,'Mapping Summary'!$D$6:$D$1820,0)) -> 0 | F34: =INDEX('Mapping Summary'!$H$6:$H$1820,MATCH('Peptide Map'!F34,'Mapping Summary'!$D$6:$D$1820,0)) -> 0 | G34: =INDEX('Mapping Summary'!$H$6:$H$1820,MATCH('Peptide Map'!G34,'Mapping Summary'!$D$6:$D$1820,0)) -> 0 | H34: =INDEX('Mapping Summary'!$H$6:$H$1820,MATCH('Peptide Map'!H34,'Mapping Summary'!$D$6:$D$1820,0)) -> 0 | I34: =INDEX('Mapping Summary'!$H$6:$H$1820,MATCH('Peptide Map'!I34,'Mapping Summary'!$D$6:$D$1820,0)) -> 0 | J34: =INDEX('Mapping Summary'!$H$6:$H$1820,MATCH('Peptide Map'!J34,'Mapping Summary'!$D$6:$D$1820,0)) -> 0 | ... P34: =INDEX('Mapping Summary'!$H$6:$H$1820,MATCH('Peptide Map'!P34,'Mapping Summary'!$D$6:$D$1820,0)) -> 0 | BQ34: G
A35: 21 | B35: YPYDVPDYAG | C35: =INDEX('Mapping Summary'!$H$6:$H$1820,MATCH('Peptide Map'!C35,'Mapping Summary'!$D$6:$D$1820,0)) -> 0 | D35: =INDEX('Mapping Summary'!$H$6:$H$1820,MATCH('Peptide Map'!D35,'Mapping Summary'!$D$6:$D$1820,0)) -> 0 | E35: =INDEX('Mapping Summary'!$H$6:$H$1820,MATCH('Peptide Map'!E35,'Mapping Summary'!$D$6:$D$1820,0)) -> 0 | F35: =INDEX('Mapping Summary'!$H$6:$H$1820,MATCH('Peptide Map'!F35,'Mapping Summary'!$D$6:$D$1820,0)) -> 0 | G35: =INDEX('Mapping Summary'!$H$6:$H$1820,MATCH('Peptide Map'!G35,'Mapping Summary'!$D$6:$D$1820,0)) -> 0 | H35: =INDEX('Mapping Summary'!$H$6:$H$1820,MATCH('Peptide Map'!H35,'Mapping Summary'!$D$6:$D$1820,0)) -> 0 | I35: =INDEX('Mapping Summary'!$H$6:$H$1820,MATCH('Peptide Map'!I35,'Mapping Summary'!$D$6:$D$1820,0)) -> 0 | J35: =INDEX('Mapping Summary'!$H$6:$H$1820,MATCH('Peptide Map'!J35,'Mapping Summary'!$D$6:$D$1820,0)) -> 0 | ... BP35: =INDEX('Mapping Summary'!$H$6:$H$1820,MATCH('Peptide Map'!BP35,'Mapping Summary'!$D$6:$D$1820,0)) -> 0 | BQ35: YPYDVPDYAG
A36: 22 | B36: G | C36: =INDEX('Mapping Summary'!$H$6:$H$1820,MATCH('Peptide Map'!C36,'Mapping Summary'!$D$6:$D$1820,0)) -> 0 | D36: =INDEX('Mapping Summary'!$H$6:$H$1820,MATCH('Peptide Map'!D36,'Mapping Summary'!$D$6:$D$1820,0)) -> 0 | E36: =INDEX('Mapping Summary'!$H$6:$H$1820,MATCH('Peptide Map'!E36,'Mapping Summary'!$D$6:$D$1820,0)) -> 0 | F36: =INDEX('Mapping Summary'!$H$6:$H$1820,MATCH('Peptide Map'!F36,'Mapping Summary'!$D$6:$D$1820,0)) -> 0 | G36: =INDEX('Mapping Summary'!$H$6:$H$1820,MATCH('Peptide Map'!G36,'Mapping Summary'!$D$6:$D$1820,0)) -> 0 | H36: =INDEX('Mapping Summary'!$H$6:$H$1820,MATCH('Peptide Map'!H36,'Mapping Summary'!$D$6:$D$1820,0)) -> 0 | I36: =INDEX('Mapping Summary'!$H$6:$H$1820,MATCH('Peptide Map'!I36,'Mapping Summary'!$D$6:$D$1820,0)) -> 0 | J36: =INDEX('Mapping Summary'!$H$6:$H$1820,MATCH('Peptide Map'!J36,'Mapping Summary'!$D$6:$D$1820,0)) -> 0 | ... BP36: =INDEX('Mapping Summary'!$H$6:$H$1820,MATCH('Peptide Map'!BP36,'Mapping Summary'!$D$6:$D$1820,0)) -> 0 | BQ36: G
A37: 23 | B37: YPYDVPDYAG | C37: =INDEX('Mapping Summary'!$H$6:$H$1820,MATCH('Peptide Map'!C37,'Mapping Summary'!$D$6:$D$1820,0)) -> 0 | D37: =INDEX('Mapping Summary'!$H$6:$H$1820,MATCH('Peptide Map'!D37,'Mapping Summary'!$D$6:$D$1820,0)) -> 0 | E37: =INDEX('Mapping Summary'!$H$6:$H$1820,MATCH('Peptide Map'!E37,'Mapping Summary'!$D$6:$D$1820,0)) -> 0 | F37: =INDEX('Mapping Summary'!$H$6:$H$1820,MATCH('Peptide Map'!F37,'Mapping Summary'!$D$6:$D$1820,0)) -> 0 | G37: =INDEX('Mapping Summary'!$H$6:$H$1820,MATCH('Peptide Map'!G37,'Mapping Summary'!$D$6:$D$1820,0)) -> 0 | H37: =INDEX('Mapping Summary'!$H$6:$H$1820,MATCH('Peptide Map'!H37,'Mapping Summary'!$D$6:$D$1820,0)) -> 0 | I37: =INDEX('Mapping Summary'!$H$6:$H$1820,MATCH('Peptide Map'!I37,'Mapping Summary'!$D$6:$D$1820,0)) -> 0 | J37: =INDEX('Mapping Summary'!$H$6:$H$1820,MATCH('Peptide Map'!J37,'Mapping Summary'!$D$6:$D$1820,0)) -> 0 | ... BP37: =INDEX('Mapping Summary'!$H$6:$H$1820,MATCH('Peptide Map'!BP37,'Mapping Summary'!$D$6:$D$1820,0)) -> 8 | BQ37: YPYDVPDYAG
A38: 24 | B38: G | C38: =INDEX('Mapping Summary'!$H$6:$H$1820,MATCH('Peptide Map'!C38,'Mapping Summary'!$D$6:$D$1820,0)) -> 0 | D38: =INDEX('Mapping Summary'!$H$6:$H$1820,MATCH('Peptide Map'!D38,'Mapping Summary'!$D$6:$D$1820,0)) -> 0 | E38: =INDEX('Mapping Summary'!$H$6:$H$1820,MATCH('Peptide Map'!E38,'Mapping Summary'!$D$6:$D$1820,0)) -> 0 | F38: =INDEX('Mapping Summary'!$H$6:$H$1820,MATCH('Peptide Map'!F38,'Mapping Summary'!$D$6:$D$1820,0)) -> 0 | G38: =INDEX('Mapping Summary'!$H$6:$H$1820,MATCH('Peptide Map'!G38,'Mapping Summary'!$D$6:$D$1820,0)) -> 0 | H38: =INDEX('Mapping Summary'!$H$6:$H$1820,MATCH('Peptide Map'!H38,'Mapping Summary'!$D$6:$D$1820,0)) -> 0 | I38: =INDEX('Mapping Summary'!$H$6:$H$1820,MATCH('Peptide Map'!I38,'Mapping Summary'!$D$6:$D$1820,0)) -> 0 | J38: =INDEX('Mapping Summary'!$H$6:$H$1820,MATCH('Peptide Map'!J38,'Mapping Summary'!$D$6:$D$1820,0)) -> 0 | ... BP38: =INDEX('Mapping Summary'!$H$6:$H$1820,MATCH('Peptide Map'!BP38,'Mapping Summary'!$D$6:$D$1820,0)) -> 8 | BQ38: G
A39: 25 | B39: YPYDVPDYAG | C39: =INDEX('Mapping Summary'!$H$6:$H$1820,MATCH('Peptide Map'!C39,'Mapping Summary'!$D$6:$D$1820,0)) -> 0 | D39: =INDEX('Mapping Summary'!$H$6:$H$1820,MATCH('Peptide Map'!D39,'Mapping Summary'!$D$6:$D$1820,0)) -> 5 | E39: =INDEX('Mapping Summary'!$H$6:$H$1820,MATCH('Peptide Map'!E39,'Mapping Summary'!$D$6:$D$1820,0)) -> 0 | F39: =INDEX('Mapping Summary'!$H$6:$H$1820,MATCH('Peptide Map'!F39,'Mapping Summary'!$D$6:$D$1820,0)) -> 3.5 | G39: =INDEX('Mapping Summary'!$H$6:$H$1820,MATCH('Peptide Map'!G39,'Mapping Summary'!$D$6:$D$1820,0)) -> 0 | H39: =INDEX('Mapping Summary'!$H$6:$H$1820,MATCH('Peptide Map'!H39,'Mapping Summary'!$D$6:$D$1820,0)) -> 0 | I39: =INDEX('Mapping Summary'!$H$6:$H$1820,MATCH('Peptide Map'!I39,'Mapping Summary'!$D$6:$D$1820,0)) -> 0 | J39: =INDEX('Mapping Summary'!$H$6:$H$1820,MATCH('Peptide Map'!J39,'Mapping Summary'!$D$6:$D$1820,0)) -> 4 | ... BP39: =INDEX('Mapping Summary'!$H$6:$H$1820,MATCH('Peptide Map'!BP39,'Mapping Summary'!$D$6:$D$1820,0)) -> 0 | BQ39: YPYDVPDYAG
A40: 26 | B40: G | C40: =INDEX('Mapping Summary'!$H$6:$H$1820,MATCH('Peptide Map'!C40,'Mapping Summary'!$D$6:$D$1820,0)) -> 0 | D40: =INDEX('Mapping Summary'!$H$6:$H$1820,MATCH('Peptide Map'!D40,'Mapping Summary'!$D$6:$D$1820,0)) -> 5 | E40: =INDEX('Mapping Summary'!$H$6:$H$1820,MATCH('Peptide Map'!E40,'Mapping Summary'!$D$6:$D$1820,0)) -> 0 | F40: =INDEX('Mapping Summary'!$H$6:$H$1820,MATCH('Peptide Map'!F40,'Mapping Summary'!$D$6:$D$1820,0)) -> 3.5 | G40: =INDEX('Mapping Summary'!$H$6:$H$1820,MATCH('Peptide Map'!G40,'Mapping Summary'!$D$6:$D$1820,0)) -> 0 | H40: =INDEX('Mapping Summary'!$H$6:$H$1820,MATCH('Peptide Map'!H40,'Mapping Summary'!$D$6:$D$1820,0)) -> 0 | I40: =INDEX('Mapping Summary'!$H$6:$H$1820,MATCH('Peptide Map'!I40,'Mapping Summary'!$D$6:$D$1820,0)) -> 0 | J40: =INDEX('Mapping Summary'!$H$6:$H$1820,MATCH('Peptide Map'!J40,'Mapping Summary'!$D$6:$D$1820,0)) -> 4 | ... BP40: =INDEX('Mapping Summary'!$H$6:$H$1820,MATCH('Peptide Map'!BP40,'Mapping Summary'!$D$6:$D$1820,0)) -> 0 | BQ40: G
A41: 27 | B41: YPYDVPDYAG | C41: =INDEX('Mapping Summary'!$H$6:$H$1820,MATCH('Peptide Map'!C41,'Mapping Summary'!$D$6:$D$1820,0)) -> 0 | D41: =INDEX('Mapping Summary'!$H$6:$H$1820,MATCH('Peptide Map'!D41,'Mapping Summary'!$D$6:$D$1820,0)) -> 0 | E41: =INDEX('Mapping Summary'!$H$6:$H$1820,MATCH('Peptide Map'!E41,'Mapping Summary'!$D$6:$D$1820,0)) -> 0 | F41: =INDEX('Mapping Summary'!$H$6:$H$1820,MATCH('Peptide Map'!F41,'Mapping Summary'!$D$6:$D$1820,0)) -> 3 | G41: =INDEX('Mapping Summary'!$H$6:$H$1820,MATCH('Peptide Map'!G41,'Mapping Summary'!$D$6:$D$1820,0)) -> 0 | H41: =INDEX('Mapping Summary'!$H$6:$H$1820,MATCH('Peptide Map'!H41,'Mapping Summary'!$D$6:$D$1820,0)) -> 2 | I41: =INDEX('Mapping Summary'!$H$6:$H$1820,MATCH('Peptide Map'!I41,'Mapping Summary'!$D$6:$D$1820,0)) -> 0 | J41: =INDEX('Mapping Summary'!$H$6:$H$1820,MATCH('Peptide Map'!J41,'Mapping Summary'!$D$6:$D$1820,0)) -> 0 | ... BP41: =INDEX('Mapping Summary'!$H$6:$H$1820,MATCH('Peptide Map'!BP41,'Mapping Summary'!$D$6:$D$1820,0)) -> 6.5 | BQ41: YPYDVPDYAG
A42: 28 | B42: G | C42: =INDEX('Mapping Summary'!$H$6:$H$1820,MATCH('Peptide Map'!C42,'Mapping Summary'!$D$6:$D$1820,0)) -> 0 | D42: =INDEX('Mapping Summary'!$H$6:$H$1820,MATCH('Peptide Map'!D42,'Mapping Summary'!$D$6:$D$1820,0)) -> 0 | E42: =INDEX('Mapping Summary'!$H$6:$H$1820,MATCH('Peptide Map'!E42,'Mapping Summary'!$D$6:$D$1820,0)) -> 0 | F42: =INDEX('Mapping Summary'!$H$6:$H$1820,MATCH('Peptide Map'!F42,'Mapping Summary'!$D$6:$D$1820,0)) -> 3 | G42: =INDEX('Mapping Summary'!$H$6:$H$1820,MATCH('Peptide Map'!G42,'Mapping Summary'!$D$6:$D$1820,0)) -> 0 | H42: =INDEX('Mapping Summary'!$H$6:$H$1820,MATCH('Peptide Map'!H42,'Mapping Summary'!$D$6:$D$1820,0)) -> 2 | I42: =INDEX('Mapping Summary'!$H$6:$H$1820,MATCH('Peptide Map'!I42,'Mapping Summary'!$D$6:$D$1820,0)) -> 0 | J42: =INDEX('Mapping Summary'!$H$6:$H$1820,MATCH('Peptide Map'!J42,'Mapping Summary'!$D$6:$D$1820,0)) -> 0 | ... BP42: =INDEX('Mapping Summary'!$H$6:$H$1820,MATCH('Peptide Map'!BP42,'Mapping Summary'!$D$6:$D$1820,0)) -> 6.5 | BQ42: G
